#VRML_SIM R2023b utf8

EXTERNPROTO "https://raw.githubusercontent.com/cyberbotics/webots/R2023b/projects/objects/backgrounds/protos/TexturedBackground.proto"
EXTERNPROTO "https://raw.githubusercontent.com/cyberbotics/webots/R2023b/projects/objects/backgrounds/protos/TexturedBackgroundLight.proto"
EXTERNPROTO "https://raw.githubusercontent.com/cyberbotics/webots/R2023b/projects/objects/floors/protos/Floor.proto"

WorldInfo {
}
Viewpoint {
  orientation -0.19786348397029083 0.10948573283023119 0.9740959480553062 2.152880204463752
  position 1.0136469276175244 -1.4289091525087494 0.9323653866086242
}
TexturedBackground {
}
TexturedBackgroundLight {
}
Floor {
}
Robot {
  translation 0 0 0.4
  children [
    Shape {
      appearance DEF base_material PBRAppearance {
        roughness 1
        metalness 0
      }
      geometry DEF base Mesh {
        url [
          "/home/guobb/Documents/GBB/0817/webots_world/DuckDuck-13DOF/meshes/base.STL"
        ]
      }
    }
    HingeJoint {
      jointParameters HingeJointParameters {
        axis 0 0 1
        anchor 0 0.04 0
      }
      device [
        RotationalMotor {
          name "left_hip_yaw_joint"
          maxTorque 10000
        }
        PositionSensor {
          name "left_hip_yaw_joint_sensor"
        }
      ]
      endPoint Solid {
        translation 0 0.04 0
        children [
          Shape {
            appearance DEF left_hip_yaw_material PBRAppearance {
              roughness 1
              metalness 0
            }
            geometry DEF left_hip_yaw Mesh {
              url [
                "/home/guobb/Documents/GBB/0817/webots_world/DuckDuck-13DOF/meshes/left_hip_yaw.STL"
              ]
            }
          }
          HingeJoint {
            jointParameters HingeJointParameters {
            }
            device [
              RotationalMotor {
                name "left_hip_roll_joint"
                maxTorque 10000
              }
              PositionSensor {
                name "left_hip_roll_joint_sensor"
              }
            ]
            endPoint Solid {
              rotation 1 0 0 0
              children [
                Shape {
                  appearance DEF left_hip_roll_material PBRAppearance {
                    roughness 1
                    metalness 0
                  }
                  geometry DEF left_hip_roll Mesh {
                    url [
                      "/home/guobb/Documents/GBB/0817/webots_world/DuckDuck-13DOF/meshes/left_hip_roll.STL"
                    ]
                  }
                }
                HingeJoint {
                  jointParameters HingeJointParameters {
                    axis 0 1 0
                  }
                  device [
                    RotationalMotor {
                      name "left_hip_pitch_joint"
                      maxTorque 10000
                    }
                    PositionSensor {
                      name "left_hip_pitch_joint_sensor"
                    }
                  ]
                  endPoint Solid {
                    rotation 0 1 0 0
                    children [
                      Shape {
                        appearance DEF left_hip_pitch_material PBRAppearance {
                          roughness 1
                          metalness 0
                        }
                        geometry DEF left_hip_pitch Mesh {
                          url [
                            "/home/guobb/Documents/GBB/0817/webots_world/DuckDuck-13DOF/meshes/left_hip_pitch.STL"
                          ]
                        }
                      }
                      HingeJoint {
                        jointParameters HingeJointParameters {
                          axis 0 1 0
                          anchor 0 0.093618 -0.14
                        }
                        device [
                          RotationalMotor {
                            name "left_knee_pitch_joint"
                            maxTorque 10000
                          }
                          PositionSensor {
                            name "left_knee_pitch_joint_sensor"
                          }
                        ]
                        endPoint Solid {
                          translation 0 0.093618 -0.14
                          rotation 0 1 0 0
                          children [
                            Shape {
                              appearance DEF left_knee_pitch_material PBRAppearance {
                                roughness 1
                                metalness 0
                              }
                              geometry DEF left_knee_pitch Mesh {
                                url [
                                  "/home/guobb/Documents/GBB/0817/webots_world/DuckDuck-13DOF/meshes/left_knee_pitch.STL"
                                ]
                              }
                            }
                            HingeJoint {
                              jointParameters HingeJointParameters {
                                axis 0 1 0
                                anchor 0 0 -0.14
                              }
                              device [
                                RotationalMotor {
                                  name "left_ankle_pitch_joint"
                                  maxTorque 10000
                                }
                                PositionSensor {
                                  name "left_ankle_pitch_joint_sensor"
                                }
                              ]
                              endPoint Solid {
                                translation 0 0 -0.14
                                rotation 0 1 0 0
                                children [
                                  Shape {
                                    appearance DEF left_ankle_pitch_material PBRAppearance {
                                      roughness 1
                                      metalness 0
                                    }
                                    geometry DEF left_ankle_pitch Mesh {
                                      url [
                                        "/home/guobb/Documents/GBB/0817/webots_world/DuckDuck-13DOF/meshes/left_ankle_pitch.STL"
                                      ]
                                    }
                                  }
                                ]
                                name "left_ankle_pitch"
                                boundingObject USE left_ankle_pitch
                                physics Physics {
                                  density -1
                                  mass 0.093421
                                  centerOfMass [
                                    0.016532 0.000879 -0.035004
                                  ]
                                  inertiaMatrix [
                                    4.082035e-05 0.0001437853 0.0001093224
                                    1.357709e-06 3.731111e-07 -2.85203e-06
                                  ]
                                }
                              }
                            }
                          ]
                          name "left_knee_pitch"
                          boundingObject USE left_knee_pitch
                          physics Physics {
                            density -1
                            mass 0.232718
                            centerOfMass [
                              0 -0.008573 -0.12701
                            ]
                            inertiaMatrix [
                              0.0002026604 0.0002498035 0.0001067836
                              6.136491e-21 -1.266704e-19 4.096347e-20
                            ]
                          }
                        }
                      }
                    ]
                    name "left_hip_pitch"
                    boundingObject USE left_hip_pitch
                    physics Physics {
                      density -1
                      mass 0.240239
                      centerOfMass [
                        0 0.084559 -0.125226
                      ]
                      inertiaMatrix [
                        0.0002251385 0.0002885958 0.0001231291
                        -4.432802e-22 -1.353577e-19 3.514217e-20
                      ]
                    }
                  }
                }
              ]
              name "left_hip_roll"
              boundingObject USE left_hip_roll
              physics Physics {
                density -1
                mass 0.227465
                centerOfMass [
                  0.000169 0.073254 -1.4e-05
                ]
                inertiaMatrix [
                  0.0001390617 0.0001542151 0.000132221
                  9.722037e-07 -3.277185e-09 5.578634e-08
                ]
              }
            }
          }
        ]
        name "left_hip_yaw"
        boundingObject USE left_hip_yaw
        physics Physics {
          density -1
          mass 0.227707
          centerOfMass [
            -0.014842 -1.4e-05 0.005181
          ]
          inertiaMatrix [
            0.0001606459 0.0001228832 0.000114845
            -1.058444e-08 2.794947e-06 5.011805e-08
          ]
        }
      }
    }
    HingeJoint {
      jointParameters HingeJointParameters {
        axis 0 0 1
        anchor 0 -0.04 0
      }
      device [
        RotationalMotor {
          name "right_hip_yaw_joint"
          maxTorque 10000
        }
        PositionSensor {
          name "right_hip_yaw_joint_sensor"
        }
      ]
      endPoint Solid {
        translation 0 -0.04 0
        children [
          Shape {
            appearance DEF right_hip_yaw_material PBRAppearance {
              roughness 1
              metalness 0
            }
            geometry DEF right_hip_yaw Mesh {
              url [
                "/home/guobb/Documents/GBB/0817/webots_world/DuckDuck-13DOF/meshes/right_hip_yaw.STL"
              ]
            }
          }
          HingeJoint {
            jointParameters HingeJointParameters {
            }
            device [
              RotationalMotor {
                name "right_hip_roll_joint"
                maxTorque 10000
              }
              PositionSensor {
                name "right_hip_roll_joint_sensor"
              }
            ]
            endPoint Solid {
              rotation 1 0 0 0
              children [
                Shape {
                  appearance DEF right_hip_roll_material PBRAppearance {
                    roughness 1
                    metalness 0
                  }
                  geometry DEF right_hip_roll Mesh {
                    url [
                      "/home/guobb/Documents/GBB/0817/webots_world/DuckDuck-13DOF/meshes/right_hip_roll.STL"
                    ]
                  }
                }
                HingeJoint {
                  jointParameters HingeJointParameters {
                    axis 0 -1 0
                  }
                  device [
                    RotationalMotor {
                      name "right_hip_pitch_joint"
                      maxTorque 10000
                    }
                    PositionSensor {
                      name "right_hip_pitch_joint_sensor"
                    }
                  ]
                  endPoint Solid {
                    rotation 0 -1 0 0
                    children [
                      Shape {
                        appearance DEF right_hip_pitch_material PBRAppearance {
                          roughness 1
                          metalness 0
                        }
                        geometry DEF right_hip_pitch Mesh {
                          url [
                            "/home/guobb/Documents/GBB/0817/webots_world/DuckDuck-13DOF/meshes/right_hip_pitch.STL"
                          ]
                        }
                      }
                      HingeJoint {
                        jointParameters HingeJointParameters {
                          axis 0 -1 0
                          anchor 0 -0.093618 -0.14
                        }
                        device [
                          RotationalMotor {
                            name "right_knee_pitch_joint"
                            maxTorque 10000
                          }
                          PositionSensor {
                            name "right_knee_pitch_joint_sensor"
                          }
                        ]
                        endPoint Solid {
                          translation 0 -0.093618 -0.14
                          rotation 0 -1 0 0
                          children [
                            Shape {
                              appearance DEF right_knee_pitch_material PBRAppearance {
                                roughness 1
                                metalness 0
                              }
                              geometry DEF right_knee_pitch Mesh {
                                url [
                                  "/home/guobb/Documents/GBB/0817/webots_world/DuckDuck-13DOF/meshes/right_knee_pitch.STL"
                                ]
                              }
                            }
                            HingeJoint {
                              jointParameters HingeJointParameters {
                                axis 0 -1 0
                                anchor 0 0 -0.14
                              }
                              device [
                                RotationalMotor {
                                  name "right_ankle_pitch_joint"
                                  maxTorque 10000
                                }
                                PositionSensor {
                                  name "right_ankle_pitch_joint_sensor"
                                }
                              ]
                              endPoint Solid {
                                translation 0 0 -0.14
                                rotation 0 -1 0 0
                                children [
                                  Shape {
                                    appearance DEF right_ankle_pitch_material PBRAppearance {
                                      roughness 1
                                      metalness 0
                                    }
                                    geometry DEF right_ankle_pitch Mesh {
                                      url [
                                        "/home/guobb/Documents/GBB/0817/webots_world/DuckDuck-13DOF/meshes/right_ankle_pitch.STL"
                                      ]
                                    }
                                  }
                                ]
                                name "right_ankle_pitch"
                                boundingObject USE right_ankle_pitch
                                physics Physics {
                                  density -1
                                  mass 0.093421
                                  centerOfMass [
                                    0.016532 -0.000879 -0.035004
                                  ]
                                  inertiaMatrix [
                                    4.082038e-05 0.0001437853 0.0001093224
                                    -1.35772e-06 3.730286e-07 2.851933e-06
                                  ]
                                }
                              }
                            }
                          ]
                          name "right_knee_pitch"
                          boundingObject USE right_knee_pitch
                          physics Physics {
                            density -1
                            mass 0.232718
                            centerOfMass [
                              0 0.008573 -0.12701
                            ]
                            inertiaMatrix [
                              0.0002026604 0.0002498035 0.0001067836
                              -3.417493e-20 -1.536569e-19 2.629276e-20
                            ]
                          }
                        }
                      }
                    ]
                    name "right_hip_pitch"
                    boundingObject USE right_hip_pitch
                    physics Physics {
                      density -1
                      mass 0.240239
                      centerOfMass [
                        0 -0.084559 -0.125226
                      ]
                      inertiaMatrix [
                        0.0002251385 0.0002885958 0.0001231291
                        -5.102767e-20 -1.597946e-19 -2.416017e-20
                      ]
                    }
                  }
                }
              ]
              name "right_hip_roll"
              boundingObject USE right_hip_roll
              physics Physics {
                density -1
                mass 0.227465
                centerOfMass [
                  0.000169 -0.073254 1.4e-05
                ]
                inertiaMatrix [
                  0.0001390617 0.0001542151 0.000132221
                  -9.722037e-07 3.277185e-09 5.578634e-08
                ]
              }
            }
          }
        ]
        name "right_hip_yaw"
        boundingObject USE right_hip_yaw
        physics Physics {
          density -1
          mass 0.227707
          centerOfMass [
            -0.014842 -1.4e-05 0.005181
          ]
          inertiaMatrix [
            0.0001606459 0.0001228832 0.000114845
            -1.058444e-08 2.794947e-06 5.011805e-08
          ]
        }
      }
    }
    HingeJoint {
      jointParameters HingeJointParameters {
        axis 0 1 0
        anchor 0.0775 0 0.10887
      }
      device [
        RotationalMotor {
          name "neck_pitch_joint"
          maxTorque 10000
        }
        PositionSensor {
          name "neck_pitch_joint_sensor"
        }
      ]
      endPoint Solid {
        translation 0.0775 0 0.10887
        rotation 0 1 0 0
        children [
          Shape {
            appearance DEF neck_pitch_material PBRAppearance {
              roughness 1
              metalness 0
            }
            geometry DEF neck_pitch Mesh {
              url [
                "/home/guobb/Documents/GBB/0817/webots_world/DuckDuck-13DOF/meshes/neck_pitch.STL"
              ]
            }
          }
          HingeJoint {
            jointParameters HingeJointParameters {
              axis -1 0 0
              anchor 0 -0.0025 0.0775
            }
            device [
              RotationalMotor {
                name "neck_roll_joint"
                maxTorque 10000
              }
              PositionSensor {
                name "neck_roll_joint_sensor"
              }
            ]
            endPoint Solid {
              translation 0 -0.0025 0.0775
              rotation -1 0 0 0
              children [
                Shape {
                  appearance DEF neck_roll_material PBRAppearance {
                    roughness 1
                    metalness 0
                  }
                  geometry DEF neck_roll Mesh {
                    url [
                      "/home/guobb/Documents/GBB/0817/webots_world/DuckDuck-13DOF/meshes/neck_roll.STL"
                    ]
                  }
                }
                HingeJoint {
                  jointParameters HingeJointParameters {
                    axis 0 0 1
                    anchor 0 0 0.061
                  }
                  device [
                    RotationalMotor {
                      name "neck_yaw_joint"
                      maxTorque 10000
                    }
                    PositionSensor {
                      name "neck_yaw_joint_sensor"
                    }
                  ]
                  endPoint Solid {
                    translation 0 0 0.061
                    children [
                      Shape {
                        appearance DEF neck_yaw_material PBRAppearance {
                          roughness 1
                          metalness 0
                        }
                        geometry DEF neck_yaw Mesh {
                          url [
                            "/home/guobb/Documents/GBB/0817/webots_world/DuckDuck-13DOF/meshes/neck_yaw.STL"
                          ]
                        }
                      }
                    ]
                    name "neck_yaw"
                    boundingObject USE neck_yaw
                    physics Physics {
                      density -1
                      mass 1.364893
                      centerOfMass [
                        -0.006017 0 0.024297
                      ]
                      inertiaMatrix [
                        0.002646118 0.004587562 0.006711535
                        -7.223176e-18 -6.370955e-05 4.407468e-19
                      ]
                    }
                  }
                }
              ]
              name "neck_roll"
              boundingObject USE neck_roll
              physics Physics {
                density -1
                mass 0.05549
                centerOfMass [
                  0 0 0.025398
                ]
                inertiaMatrix [
                  3.521556e-05 2.952544e-05 9.347601e-06
                  1.761745e-20 -3.760481e-20 -6.051811e-21
                ]
              }
            }
          }
        ]
        name "neck_pitch"
        boundingObject USE neck_pitch
        physics Physics {
          density -1
          mass 0.094414
          centerOfMass [
            0 -0.0025 0.050093
          ]
          inertiaMatrix [
            5.982277e-05 5.752288e-05 3.405908e-05
            8.645206e-21 -3.324769e-20 -1.139153e-20
          ]
        }
      }
    }
  ]
  name "DuckDuck"
  boundingObject USE base
  physics Physics {
    density -1
    mass 1.700374
    centerOfMass [
      -0.010093 -8.5e-05 0.041711
    ]
    inertiaMatrix [
      0.01102631 0.01721595 0.01518094
      1.156032e-08 0.0001853957 -8.115702e-09
    ]
  }
}
