#VRML_SIM R2023b utf8
# license: Apache License 2.0
# license url: http://www.apache.org/licenses/LICENSE-2.0
# This is a proto file for Webots for the AdamLiteSimple
# Extracted from: /home/g/Documents/0817/webots_world/adam_lite_simple/urdf/adam_lite_simple.urdf

PROTO AdamLiteSimple [
  field  SFVec3f     translation     0 0 0
  field  SFRotation  rotation        0 0 1 0
  field  SFString    name            "AdamLiteSimple"  # Is `Robot.name`.
  field  SFString    controller      "void"            # Is `Robot.controller`.
  field  MFString    controllerArgs  []                # Is `Robot.controllerArgs`.
  field  SFString    customData      ""                # Is `Robot.customData`.
  field  SFBool      supervisor      FALSE             # Is `Robot.supervisor`.
  field  SFBool      synchronization TRUE              # Is `Robot.synchronization`.
  field  SFBool      selfCollision   FALSE             # Is `Robot.selfCollision`.
]
{
  Robot {
    translation IS translation
    rotation IS rotation
    controller IS controller
    controllerArgs IS controllerArgs
    customData IS customData
    supervisor IS supervisor
    synchronization IS synchronization
    selfCollision IS selfCollision
    children [
      Shape {
        appearance DEF pelvis_material PBRAppearance {
          roughness 1.000000
          metalness 0
        }
        geometry DEF pelvis Mesh {
          url "../meshes/pelvis.STL"
        }
      }
      HingeJoint {
        jointParameters HingeJointParameters {
          axis 0.000000 0.819149 -0.573580
          anchor 0.000000 0.096192 -0.033241
        }
        device [
          RotationalMotor {
            name "hipPitch_Left"
            maxVelocity 15.0
            minPosition -2.09
            maxPosition 2.09
            maxTorque 230.0
          }
          PositionSensor {
            name "hipPitch_Left_sensor"
          }
        ]
        endPoint Solid {
          translation 0.000000 0.096192 -0.033241
          rotation -1.000000 0.000000 0.000000 0.610870
          children [
            Shape {
              appearance DEF hipPitchLeft_material PBRAppearance {
                roughness 1.000000
                metalness 0
              }
              geometry DEF hipPitchLeft Mesh {
                url "../meshes/hipPitchLeft.STL"
              }
            }
            HingeJoint {
              jointParameters HingeJointParameters {
                anchor -0.025500 0.069000 0.000000
              }
              device [
                RotationalMotor {
                  name "hipRoll_Left"
                  maxVelocity 8.0
                  minPosition -0.78
                  maxPosition 1.57
                  maxTorque 160.0
                }
                PositionSensor {
                  name "hipRoll_Left_sensor"
                }
              ]
              endPoint Solid {
                translation -0.025500 0.069000 0.000000
                rotation 1.000000 0.000000 0.000000 0.610870
                children [
                  Shape {
                    appearance DEF hipRollLeft_material PBRAppearance {
                      roughness 1.000000
                      metalness 0
                    }
                    geometry DEF hipRollLeft Mesh {
                      url "../meshes/hipRollLeft.STL"
                    }
                  }
                  HingeJoint {
                    jointParameters HingeJointParameters {
                      axis 0.000000 0.000000 1.000000
                      anchor 0.044000 0.000000 -0.052500
                    }
                    device [
                      RotationalMotor {
                        name "hipYaw_Left"
                        maxVelocity 8.0
                        minPosition -0.78
                        maxPosition 0.78
                        maxTorque 105.0
                      }
                      PositionSensor {
                        name "hipYaw_Left_sensor"
                      }
                    ]
                    endPoint Solid {
                      translation 0.044000 0.000000 -0.052500
                      children [
                        Shape {
                          appearance DEF thighLeft_material PBRAppearance {
                            roughness 1.000000
                            metalness 0
                          }
                          geometry DEF thighLeft Mesh {
                            url "../meshes/thighLeft.STL"
                          }
                        }
                        HingeJoint {
                          jointParameters HingeJointParameters {
                            axis 0.000000 1.000000 0.000000
                            anchor 0.000000 -0.035500 -0.369000
                          }
                          device [
                            RotationalMotor {
                              name "kneePitch_Left"
                              maxVelocity 15.0
                              minPosition -0.09
                              maxPosition 2.4
                              maxTorque 230.0
                            }
                            PositionSensor {
                              name "kneePitch_Left_sensor"
                            }
                          ]
                          endPoint Solid {
                            translation 0.000000 -0.035500 -0.369000
                            children [
                              Shape {
                                appearance DEF shinLeft_material PBRAppearance {
                                  roughness 1.000000
                                  metalness 0
                                }
                                geometry DEF shinLeft Mesh {
                                  url "../meshes/shinLeft.STL"
                                }
                              }
                              HingeJoint {
                                jointParameters HingeJointParameters {
                                  axis 0.000000 1.000000 0.000000
                                  anchor 0.000000 0.000000 -0.370000
                                }
                                device [
                                  RotationalMotor {
                                    name "anklePitch_Left"
                                    maxVelocity 20.0
                                    minPosition -1.0
                                    maxPosition 0.35
                                    maxTorque 40.0
                                  }
                                  PositionSensor {
                                    name "anklePitch_Left_sensor"
                                  }
                                ]
                                endPoint Solid {
                                  translation 0.000000 0.000000 -0.370000
                                  children [
                                    Shape {
                                      appearance DEF anklePitchLeft_material PBRAppearance {
                                        roughness 1.000000
                                        metalness 0
                                      }
                                      geometry DEF anklePitchLeft Mesh {
                                        url "../meshes/anklePitchLeft.STL"
                                      }
                                    }
                                    HingeJoint {
                                      jointParameters HingeJointParameters {
                                      }
                                      device [
                                        RotationalMotor {
                                          name "ankleRoll_Left"
                                          maxVelocity 20.0
                                          minPosition -0.3491
                                          maxPosition 0.3491
                                          maxTorque 12.0
                                        }
                                        PositionSensor {
                                          name "ankleRoll_Left_sensor"
                                        }
                                      ]
                                      endPoint Solid {
                                        children [
                                          Shape {
                                            appearance DEF toeLeft_material PBRAppearance {
                                              baseColor 0.752941 0.752941 0.752941
                                              roughness 1.000000
                                              metalness 0
                                            }
                                            geometry DEF toeLeft Mesh {
                                              url "../meshes/toeLeft.STL"
                                            }
                                          }
                                        ]
                                        name "toeLeft"
                                        boundingObject Pose {
                                          translation 0.047000 0.000000 -0.050000
                                          children [
                                            Box {
                                               size 0.240000 0.100000 0.030000
                                            }
                                          ]
                                        }
                                        physics Physics {
                                          density -1
                                          mass 0.475800
                                          centerOfMass [ 0.037007 -0.000021 -0.041987 ]
                                          inertiaMatrix [
                                            2.849200e-04 1.521810e-03 1.581870e-03
                                            1.326000e-05 -1.202300e-04 1.430000e-06
                                          ]
                                        }
                                      }
                                    }
                                  ]
                                  name "anklePitchLeft"
                                  physics Physics {
                                    density -1
                                    mass 0.031000
                                    centerOfMass [ 0.000000 0.000000 0.000000 ]
                                    inertiaMatrix [
                                      3.230000e-06 3.230000e-06 2.100000e-06
                                      0.000000e+00 0.000000e+00 0.000000e+00
                                    ]
                                  }
                                }
                              }
                            ]
                            name "shinLeft"
                            boundingObject Pose {
                              translation 0.000000 0.000000 -0.200000
                              children [
                                Box {
                                   size 0.080000 0.060000 0.300000
                                }
                              ]
                            }
                            physics Physics {
                              density -1
                              mass 2.198665
                              centerOfMass [ -0.000809 0.000973 -0.145408 ]
                              inertiaMatrix [
                                1.932815e-02 1.940985e-02 1.368280e-03
                                -1.127000e-05 2.201200e-04 8.606000e-05
                              ]
                            }
                          }
                        }
                      ]
                      name "thighLeft"
                      physics Physics {
                        density -1
                        mass 6.647497
                        centerOfMass [ 0.003312 -0.011125 -0.135198 ]
                        inertiaMatrix [
                          5.688222e-02 6.217155e-02 1.520394e-02
                          -3.181300e-04 -1.565310e-03 5.318380e-03
                        ]
                      }
                    }
                  }
                ]
                name "hipRollLeft"
                physics Physics {
                  density -1
                  mass 1.294219
                  centerOfMass [ 0.039954 -0.000116 -0.011021 ]
                  inertiaMatrix [
                    1.341680e-03 1.370700e-03 1.445770e-03
                    -4.310000e-06 -6.007000e-05 -1.695000e-05
                  ]
                }
              }
            }
          ]
          name "hipPitchLeft"
          physics Physics {
            density -1
            mass 2.151248
            centerOfMass [ -0.058182 0.058895 -0.000312 ]
            inertiaMatrix [
              3.858470e-03 4.409730e-03 5.080850e-03
              -9.445500e-04 2.598000e-05 2.828000e-05
            ]
          }
        }
      }
      HingeJoint {
        jointParameters HingeJointParameters {
          axis 0.000000 0.819149 0.573580
          anchor 0.000000 -0.096192 -0.033241
        }
        device [
          RotationalMotor {
            name "hipPitch_Right"
            maxVelocity 15.0
            minPosition -2.09
            maxPosition 2.09
            maxTorque 230.0
          }
          PositionSensor {
            name "hipPitch_Right_sensor"
          }
        ]
        endPoint Solid {
          translation 0.000000 -0.096192 -0.033241
          rotation 1.000000 0.000000 0.000000 0.610870
          children [
            Shape {
              appearance DEF hipPitchRight_material PBRAppearance {
                roughness 1.000000
                metalness 0
              }
              geometry DEF hipPitchRight Mesh {
                url "../meshes/hipPitchRight.STL"
              }
            }
            HingeJoint {
              jointParameters HingeJointParameters {
                anchor -0.025500 -0.069000 0.000000
              }
              device [
                RotationalMotor {
                  name "hipRoll_Right"
                  maxVelocity 8.0
                  minPosition -1.57
                  maxPosition 0.78
                  maxTorque 160.0
                }
                PositionSensor {
                  name "hipRoll_Right_sensor"
                }
              ]
              endPoint Solid {
                translation -0.025500 -0.069000 0.000000
                rotation -1.000000 0.000000 0.000000 0.610870
                children [
                  Shape {
                    appearance DEF hipRollRight_material PBRAppearance {
                      roughness 1.000000
                      metalness 0
                    }
                    geometry DEF hipRollRight Mesh {
                      url "../meshes/hipRollRight.STL"
                    }
                  }
                  HingeJoint {
                    jointParameters HingeJointParameters {
                      axis 0.000000 0.000000 1.000000
                      anchor 0.044000 0.000000 -0.052500
                    }
                    device [
                      RotationalMotor {
                        name "hipYaw_Right"
                        maxVelocity 8.0
                        minPosition -0.78
                        maxPosition 0.78
                        maxTorque 105.0
                      }
                      PositionSensor {
                        name "hipYaw_Right_sensor"
                      }
                    ]
                    endPoint Solid {
                      translation 0.044000 0.000000 -0.052500
                      children [
                        Shape {
                          appearance DEF thighRight_material PBRAppearance {
                            roughness 1.000000
                            metalness 0
                          }
                          geometry DEF thighRight Mesh {
                            url "../meshes/thighRight.STL"
                          }
                        }
                        HingeJoint {
                          jointParameters HingeJointParameters {
                            axis 0.000000 1.000000 0.000000
                            anchor 0.000000 0.035500 -0.369000
                          }
                          device [
                            RotationalMotor {
                              name "kneePitch_Right"
                              maxVelocity 15.0
                              minPosition -0.09
                              maxPosition 2.4
                              maxTorque 230.0
                            }
                            PositionSensor {
                              name "kneePitch_Right_sensor"
                            }
                          ]
                          endPoint Solid {
                            translation 0.000000 0.035500 -0.369000
                            children [
                              Shape {
                                appearance DEF shinRight_material PBRAppearance {
                                  roughness 1.000000
                                  metalness 0
                                }
                                geometry DEF shinRight Mesh {
                                  url "../meshes/shinRight.STL"
                                }
                              }
                              HingeJoint {
                                jointParameters HingeJointParameters {
                                  axis 0.000000 1.000000 0.000000
                                  anchor 0.000000 0.000000 -0.370000
                                }
                                device [
                                  RotationalMotor {
                                    name "anklePitch_Right"
                                    maxVelocity 20.0
                                    minPosition -1.0
                                    maxPosition 0.35
                                    maxTorque 40.0
                                  }
                                  PositionSensor {
                                    name "anklePitch_Right_sensor"
                                  }
                                ]
                                endPoint Solid {
                                  translation 0.000000 0.000000 -0.370000
                                  children [
                                    Shape {
                                      appearance DEF anklePitchRight_material PBRAppearance {
                                        baseColor 0.752941 0.752941 0.752941
                                        roughness 1.000000
                                        metalness 0
                                      }
                                      geometry DEF anklePitchRight Mesh {
                                        url "../meshes/anklePitchRight.STL"
                                      }
                                    }
                                    HingeJoint {
                                      jointParameters HingeJointParameters {
                                      }
                                      device [
                                        RotationalMotor {
                                          name "ankleRoll_Right"
                                          maxVelocity 20.0
                                          minPosition -0.3491
                                          maxPosition 0.3491
                                          maxTorque 12.0
                                        }
                                        PositionSensor {
                                          name "ankleRoll_Right_sensor"
                                        }
                                      ]
                                      endPoint Solid {
                                        children [
                                          Shape {
                                            appearance DEF toeRight_material PBRAppearance {
                                              baseColor 0.752941 0.752941 0.752941
                                              roughness 1.000000
                                              metalness 0
                                            }
                                            geometry DEF toeRight Mesh {
                                              url "../meshes/toeRight.STL"
                                            }
                                          }
                                        ]
                                        name "toeRight"
                                        boundingObject Pose {
                                          translation 0.047000 0.000000 -0.050000
                                          children [
                                            Box {
                                               size 0.240000 0.100000 0.030000
                                            }
                                          ]
                                        }
                                        physics Physics {
                                          density -1
                                          mass 0.475800
                                          centerOfMass [ 0.037003 0.000022 -0.041976 ]
                                          inertiaMatrix [
                                            2.852200e-04 1.521910e-03 1.581640e-03
                                            -1.320000e-05 -1.203400e-04 -1.430000e-06
                                          ]
                                        }
                                      }
                                    }
                                  ]
                                  name "anklePitchRight"
                                  physics Physics {
                                    density -1
                                    mass 0.031000
                                    centerOfMass [ 0.000000 0.000000 0.000000 ]
                                    inertiaMatrix [
                                      3.230000e-06 3.230000e-06 2.100000e-06
                                      0.000000e+00 0.000000e+00 0.000000e+00
                                    ]
                                  }
                                }
                              }
                            ]
                            name "shinRight"
                            boundingObject Pose {
                              translation 0.000000 0.000000 -0.200000
                              children [
                                Box {
                                   size 0.080000 0.060000 0.300000
                                }
                              ]
                            }
                            physics Physics {
                              density -1
                              mass 2.208092
                              centerOfMass [ -0.000800 -0.000973 -0.146351 ]
                              inertiaMatrix [
                                1.979830e-02 1.987660e-02 1.371920e-03
                                1.096000e-05 2.175800e-04 -9.064000e-05
                              ]
                            }
                          }
                        }
                      ]
                      name "thighRight"
                      physics Physics {
                        density -1
                        mass 6.647545
                        centerOfMass [ 0.003327 0.011103 -0.135290 ]
                        inertiaMatrix [
                          5.714386e-02 6.243248e-02 1.517531e-02
                          3.027700e-04 -1.538830e-03 -5.311340e-03
                        ]
                      }
                    }
                  }
                ]
                name "hipRollRight"
                physics Physics {
                  density -1
                  mass 1.294228
                  centerOfMass [ 0.039882 0.000116 -0.011021 ]
                  inertiaMatrix [
                    1.341700e-03 1.369970e-03 1.445020e-03
                    3.790000e-06 -6.269000e-05 1.693000e-05
                  ]
                }
              }
            }
          ]
          name "hipPitchRight"
          physics Physics {
            density -1
            mass 2.151243
            centerOfMass [ -0.058182 -0.058870 -0.000330 ]
            inertiaMatrix [
              3.857350e-03 4.406700e-03 5.082800e-03
              9.421000e-04 2.770000e-05 -2.677000e-05
            ]
          }
        }
      }
    ]
    name IS name
    boundingObject Pose {
      rotation 1.000000 0.000000 0.000000 1.570000
      children [
        Cylinder {
          radius 0.1
          height 0.2
        }
      ]
    }
    physics Physics {
      density -1
      mass 10.187300
      centerOfMass [ -0.001203 -0.000001 -0.008022 ]
      inertiaMatrix [
        6.839529e-02 3.753230e-02 7.519708e-02
        -9.950000e-06 -4.308000e-05 -1.050000e-06
      ]
    }
  }
}
