#VRML_SIM R2023b utf8

EXTERNPROTO "https://raw.githubusercontent.com/cyberbotics/webots/R2023b/projects/objects/backgrounds/protos/TexturedBackground.proto"
EXTERNPROTO "https://raw.githubusercontent.com/cyberbotics/webots/R2023b/projects/objects/backgrounds/protos/TexturedBackgroundLight.proto"
EXTERNPROTO "https://raw.githubusercontent.com/cyberbotics/webots/R2023b/projects/objects/floors/protos/RectangleArena.proto"

WorldInfo {
}
Viewpoint {
  orientation -0.09511250963721582 0.05450977750682205 0.9939729848776915 2.1060073151968797
  position 1.6805674499800056 -2.542539413094005 0.9295155527203223
}
TexturedBackground {
}
TexturedBackgroundLight {
}
RectangleArena {
  floorSize 10 10
}
Robot {
  translation 0 0 0.4
  children [
    Shape {
      appearance DEF base_material PBRAppearance {
        roughness 1
        metalness 0
      }
      geometry DEF base Mesh {
        url [
          "/home/g/Documents/0817/webots_world/DuckDuck/meshes/base.STL"
        ]
      }
    }
    HingeJoint {
      jointParameters HingeJointParameters {
        axis 0 0 1
        anchor 0 0.04 0
      }
      device [
        RotationalMotor {
          name "left_hip_yaw_joint"
          maxTorque 10000
        }
        PositionSensor {
          name "left_hip_yaw_joint_sensor"
        }
      ]
      endPoint Solid {
        translation 0 0.04 0
        children [
          Shape {
            appearance DEF left_hip_yaw_material PBRAppearance {
              roughness 1
              metalness 0
            }
            geometry DEF left_hip_yaw Mesh {
              url [
                "/home/g/Documents/0817/webots_world/DuckDuck/meshes/left_hip_yaw.STL"
              ]
            }
          }
          HingeJoint {
            jointParameters HingeJointParameters {
            }
            device [
              RotationalMotor {
                name "left_hip_roll_joint"
                maxTorque 10000
              }
              PositionSensor {
                name "left_hip_roll_joint_sensor"
              }
            ]
            endPoint Solid {
              rotation 1 0 0 0
              children [
                Shape {
                  appearance DEF left_hip_roll_material PBRAppearance {
                    roughness 1
                    metalness 0
                  }
                  geometry DEF left_hip_roll Mesh {
                    url [
                      "/home/g/Documents/0817/webots_world/DuckDuck/meshes/left_hip_roll.STL"
                    ]
                  }
                }
                HingeJoint {
                  jointParameters HingeJointParameters {
                    axis 0 1 0
                  }
                  device [
                    RotationalMotor {
                      name "left_hip_pitch_joint"
                      maxTorque 10000
                    }
                    PositionSensor {
                      name "left_hip_pitch_joint_sensor"
                    }
                  ]
                  endPoint Solid {
                    rotation 0 1 0 0
                    children [
                      Shape {
                        appearance DEF left_hip_pitch_material PBRAppearance {
                          roughness 1
                          metalness 0
                        }
                        geometry DEF left_hip_pitch Mesh {
                          url [
                            "/home/g/Documents/0817/webots_world/DuckDuck/meshes/left_hip_pitch.STL"
                          ]
                        }
                      }
                      HingeJoint {
                        jointParameters HingeJointParameters {
                          axis 0 1 0
                          anchor 0 0.093618 -0.14
                        }
                        device [
                          RotationalMotor {
                            name "left_knee_pitch_joint"
                            maxTorque 10000
                          }
                          PositionSensor {
                            name "left_knee_pitch_joint_sensor"
                          }
                        ]
                        endPoint Solid {
                          translation 0 0.093618 -0.14
                          rotation 0 1 0 0
                          children [
                            Shape {
                              appearance DEF left_knee_pitch_material PBRAppearance {
                                roughness 1
                                metalness 0
                              }
                              geometry DEF left_knee_pitch Mesh {
                                url [
                                  "/home/g/Documents/0817/webots_world/DuckDuck/meshes/left_knee_pitch.STL"
                                ]
                              }
                            }
                            HingeJoint {
                              jointParameters HingeJointParameters {
                                axis 0 1 0
                                anchor 0 0 -0.14
                              }
                              device [
                                RotationalMotor {
                                  name "left_ankle_pitch_joint"
                                  maxTorque 10000
                                }
                                PositionSensor {
                                  name "left_ankle_pitch_joint_sensor"
                                }
                              ]
                              endPoint Solid {
                                translation 0 0 -0.14
                                rotation 0 1 0 0
                                children [
                                  Shape {
                                    appearance DEF left_ankle_pitch_material PBRAppearance {
                                      roughness 1
                                      metalness 0
                                    }
                                    geometry DEF left_ankle_pitch Mesh {
                                      url [
                                        "/home/g/Documents/0817/webots_world/DuckDuck/meshes/left_ankle_pitch.STL"
                                      ]
                                    }
                                  }
                                ]
                                name "left_ankle_pitch"
                                boundingObject USE left_ankle_pitch
                                physics Physics {
                                  density -1
                                  mass 0.093421
                                  centerOfMass [
                                    0.016532 0.000879 -0.035004
                                  ]
                                  inertiaMatrix [
                                    4.082035e-05 0.0001437853 0.0001093224
                                    1.357709e-06 3.731111e-07 -2.85203e-06
                                  ]
                                }
                              }
                            }
                          ]
                          name "left_knee_pitch"
                          boundingObject USE left_knee_pitch
                          physics Physics {
                            density -1
                            mass 0.232718
                            centerOfMass [
                              0 -0.008573 -0.12701
                            ]
                            inertiaMatrix [
                              0.0002026604 0.0002498035 0.0001067836
                              3.879377e-21 -1.289525e-19 4.277976e-20
                            ]
                          }
                        }
                      }
                    ]
                    name "left_hip_pitch"
                    boundingObject USE left_hip_pitch
                    physics Physics {
                      density -1
                      mass 0.240239
                      centerOfMass [
                        0 0.084559 -0.125226
                      ]
                      inertiaMatrix [
                        0.0002251385 0.0002885958 0.0001231291
                        9.531081e-22 -1.346001e-19 3.537595e-20
                      ]
                    }
                  }
                }
              ]
              name "left_hip_roll"
              boundingObject USE left_hip_roll
              physics Physics {
                density -1
                mass 0.227465
                centerOfMass [
                  0.000169 0.073254 -1.4e-05
                ]
                inertiaMatrix [
                  0.0001390617 0.0001542151 0.000132221
                  9.722037e-07 -3.277185e-09 5.578634e-08
                ]
              }
            }
          }
        ]
        name "left_hip_yaw"
        boundingObject USE left_hip_yaw
        physics Physics {
          density -1
          mass 0.227707
          centerOfMass [
            -0.014842 -1.4e-05 0.005181
          ]
          inertiaMatrix [
            0.0001606459 0.0001228832 0.000114845
            -1.058444e-08 2.794947e-06 5.011805e-08
          ]
        }
      }
    }
    HingeJoint {
      jointParameters HingeJointParameters {
        axis 0 0 1
        anchor 0 -0.04 0
      }
      device [
        RotationalMotor {
          name "right_hip_yaw_joint"
          maxTorque 10000
        }
        PositionSensor {
          name "right_hip_yaw_joint_sensor"
        }
      ]
      endPoint Solid {
        translation 0 -0.04 0
        children [
          Shape {
            appearance DEF right_hip_yaw_material PBRAppearance {
              roughness 1
              metalness 0
            }
            geometry DEF right_hip_yaw Mesh {
              url [
                "/home/g/Documents/0817/webots_world/DuckDuck/meshes/right_hip_yaw.STL"
              ]
            }
          }
          HingeJoint {
            jointParameters HingeJointParameters {
            }
            device [
              RotationalMotor {
                name "right_hip_roll_joint"
                maxTorque 10000
              }
              PositionSensor {
                name "right_hip_roll_joint_sensor"
              }
            ]
            endPoint Solid {
              rotation 1 0 0 0
              children [
                Shape {
                  appearance DEF right_hip_roll_material PBRAppearance {
                    roughness 1
                    metalness 0
                  }
                  geometry DEF right_hip_roll Mesh {
                    url [
                      "/home/g/Documents/0817/webots_world/DuckDuck/meshes/right_hip_roll.STL"
                    ]
                  }
                }
                HingeJoint {
                  jointParameters HingeJointParameters {
                    axis 0 -1 0
                  }
                  device [
                    RotationalMotor {
                      name "right_hip_pitch_joint"
                      maxTorque 10000
                    }
                    PositionSensor {
                      name "right_hip_pitch_joint_sensor"
                    }
                  ]
                  endPoint Solid {
                    rotation 0 -1 0 0
                    children [
                      Shape {
                        appearance DEF right_hip_pitch_material PBRAppearance {
                          roughness 1
                          metalness 0
                        }
                        geometry DEF right_hip_pitch Mesh {
                          url [
                            "/home/g/Documents/0817/webots_world/DuckDuck/meshes/right_hip_pitch.STL"
                          ]
                        }
                      }
                      HingeJoint {
                        jointParameters HingeJointParameters {
                          axis 0 -1 0
                          anchor 0 -0.093618 -0.14
                        }
                        device [
                          RotationalMotor {
                            name "right_knee_pitch_joint"
                            maxTorque 10000
                          }
                          PositionSensor {
                            name "right_knee_pitch_joint_sensor"
                          }
                        ]
                        endPoint Solid {
                          translation 0 -0.093618 -0.14
                          rotation 0 -1 0 0
                          children [
                            Shape {
                              appearance DEF right_knee_pitch_material PBRAppearance {
                                roughness 1
                                metalness 0
                              }
                              geometry DEF right_knee_pitch Mesh {
                                url [
                                  "/home/g/Documents/0817/webots_world/DuckDuck/meshes/right_knee_pitch.STL"
                                ]
                              }
                            }
                            HingeJoint {
                              jointParameters HingeJointParameters {
                                axis 0 -1 0
                                anchor 0 0 -0.14
                              }
                              device [
                                RotationalMotor {
                                  name "right_ankle_pitch_joint"
                                  maxTorque 10000
                                }
                                PositionSensor {
                                  name "right_ankle_pitch_joint_sensor"
                                }
                              ]
                              endPoint Solid {
                                translation 0 0 -0.14
                                rotation 0 -1 0 0
                                children [
                                  Shape {
                                    appearance DEF right_ankle_pitch_material PBRAppearance {
                                      roughness 1
                                      metalness 0
                                    }
                                    geometry DEF right_ankle_pitch Mesh {
                                      url [
                                        "/home/g/Documents/0817/webots_world/DuckDuck/meshes/right_ankle_pitch.STL"
                                      ]
                                    }
                                  }
                                ]
                                name "right_ankle_pitch"
                                boundingObject USE right_ankle_pitch
                                physics Physics {
                                  density -1
                                  mass 0.093421
                                  centerOfMass [
                                    0.016532 -0.000879 -0.035004
                                  ]
                                  inertiaMatrix [
                                    4.082038e-05 0.0001437853 0.0001093224
                                    -1.35772e-06 3.730286e-07 2.851933e-06
                                  ]
                                }
                              }
                            }
                          ]
                          name "right_knee_pitch"
                          boundingObject USE right_knee_pitch
                          physics Physics {
                            density -1
                            mass 0.232718
                            centerOfMass [
                              0 0.008573 -0.12701
                            ]
                            inertiaMatrix [
                              0.0002026604 0.0002498035 0.0001067836
                              -3.419171e-20 -1.536186e-19 2.62948e-20
                            ]
                          }
                        }
                      }
                    ]
                    name "right_hip_pitch"
                    boundingObject USE right_hip_pitch
                    physics Physics {
                      density -1
                      mass 0.240239
                      centerOfMass [
                        0 -0.084559 -0.125226
                      ]
                      inertiaMatrix [
                        0.0002251385 0.0002885958 0.0001231291
                        -5.102168e-20 -1.597564e-19 -2.422759e-20
                      ]
                    }
                  }
                }
              ]
              name "right_hip_roll"
              boundingObject USE right_hip_roll
              physics Physics {
                density -1
                mass 0.227465
                centerOfMass [
                  0.000169 -0.073254 1.4e-05
                ]
                inertiaMatrix [
                  0.0001390617 0.0001542151 0.000132221
                  -9.722037e-07 3.277185e-09 5.578634e-08
                ]
              }
            }
          }
        ]
        name "right_hip_yaw"
        boundingObject USE right_hip_yaw
        physics Physics {
          density -1
          mass 0.227707
          centerOfMass [
            -0.014842 -1.4e-05 0.005181
          ]
          inertiaMatrix [
            0.0001606459 0.0001228832 0.000114845
            -1.058444e-08 2.794947e-06 5.011805e-08
          ]
        }
      }
    }
    HingeJoint {
      jointParameters HingeJointParameters {
        axis 0 1 0
        anchor 0.0775 0 0.108875
      }
      device [
        RotationalMotor {
          name "neck_pitch1_joint"
          maxTorque 10000
        }
        PositionSensor {
          name "neck_pitch1_joint_sensor"
        }
      ]
      endPoint Solid {
        translation 0.0775 0 0.108875
        rotation 0 1 0 0
        children [
          Shape {
            appearance DEF neck_pitch1_material PBRAppearance {
              roughness 1
              metalness 0
            }
            geometry DEF neck_pitch1 Mesh {
              url [
                "/home/g/Documents/0817/webots_world/DuckDuck/meshes/neck_pitch1.STL"
              ]
            }
          }
          HingeJoint {
            jointParameters HingeJointParameters {
              axis 0 -1 0
              anchor 0 0 0.08
            }
            device [
              RotationalMotor {
                name "neck_pitch2_joint"
                maxTorque 10000
              }
              PositionSensor {
                name "neck_pitch2_joint_sensor"
              }
            ]
            endPoint Solid {
              translation 0 0 0.08
              rotation 0 -1 0 0
              children [
                Shape {
                  appearance DEF neck_pitch2_material PBRAppearance {
                    roughness 1
                    metalness 0
                  }
                  geometry DEF neck_pitch2 Mesh {
                    url [
                      "/home/g/Documents/0817/webots_world/DuckDuck/meshes/neck_pitch2.STL"
                    ]
                  }
                }
              ]
              name "neck_pitch2"
              boundingObject USE neck_pitch2
              physics Physics {
                density -1
                mass 1.420181
                centerOfMass [
                  0.005759 -0.0025 0.081999
                ]
                inertiaMatrix [
                  0.002674372 0.004621543 0.006720913
                  -6.519399e-18 -6.35778e-05 7.233972e-19
                ]
              }
            }
          }
        ]
        name "neck_pitch1"
        boundingObject USE neck_pitch1
        physics Physics {
          density -1
          mass 0.100524
          centerOfMass [
            0 -0.0025 0.051045
          ]
          inertiaMatrix [
            6.476353e-05 5.842212e-05 3.580202e-05
            1.989565e-20 -3.157087e-20 -7.672768e-21
          ]
        }
      }
    }
  ]
  name "DuckDuck"
  boundingObject USE base
  physics Physics {
    density -1
    mass 1.700374
    centerOfMass [
      -0.010093 -8.5e-05 0.041711
    ]
    inertiaMatrix [
      0.01102631 0.01721595 0.01518094
      1.156032e-08 0.0001853957 -8.115702e-09
    ]
  }
}
