#VRML_SIM R2023b utf8

EXTERNPROTO "https://raw.githubusercontent.com/cyberbotics/webots/R2023b/projects/objects/backgrounds/protos/TexturedBackground.proto"
EXTERNPROTO "https://raw.githubusercontent.com/cyberbotics/webots/R2023b/projects/objects/backgrounds/protos/TexturedBackgroundLight.proto"
EXTERNPROTO "https://raw.githubusercontent.com/cyberbotics/webots/R2023b/projects/objects/floors/protos/RectangleArena.proto"

WorldInfo {
  basicTimeStep 1.25
}
Viewpoint {
  orientation 0.08278777035146948 0.39893823740283946 -0.9132329756519681 0.44685098926583655
  position -0.6187319228937426 0.3334105480840757 0.349248555532053
}
TexturedBackground {
}
TexturedBackgroundLight {
}
RectangleArena {
  floorSize 10 10
}
DEF Adam Robot {
  translation 0 0 0.98
  children [
    Pose {
      children [
        InertialUnit {
        }
        Gyro {
        }
        Accelerometer {
        }
      ]
    }
    Shape {
      appearance DEF pelvis_material PBRAppearance {
        roughness 1
        metalness 0
      }
      geometry DEF pelvis Mesh {
        url [
          "../meshes_lite_simple/pelvis.STL"
        ]
      }
    }
    HingeJoint {
      jointParameters HingeJointParameters {
        axis 0 0.819149 -0.57358
        anchor 0 0.096192 -0.033241
      }
      device [
        RotationalMotor {
          name "hipPitch_Left"
          maxVelocity 15
          minPosition -2.09
          maxPosition 2.09
          maxTorque 230
        }
        PositionSensor {
          name "hipPitch_Left_sensor"
        }
      ]
      endPoint Solid {
        translation 0 0.096192 -0.033241
        rotation -1 0 0 0.6108700000000002
        children [
          Shape {
            appearance DEF hipPitchLeft_material PBRAppearance {
              roughness 1
              metalness 0
            }
            geometry DEF hipPitchLeft Mesh {
              url [
                "../meshes_lite_simple/hipPitchLeft.STL"
              ]
            }
          }
          HingeJoint {
            jointParameters HingeJointParameters {
              anchor -0.0255 0.069 0
            }
            device [
              RotationalMotor {
                name "hipRoll_Left"
                maxVelocity 8
                minPosition -0.78
                maxPosition 1.57
                maxTorque 160
              }
              PositionSensor {
                name "hipRoll_Left_sensor"
              }
            ]
            endPoint Solid {
              translation -0.0255 0.069 0
              rotation 1 0 0 0.6108700000000002
              children [
                Shape {
                  appearance DEF hipRollLeft_material PBRAppearance {
                    roughness 1
                    metalness 0
                  }
                  geometry DEF hipRollLeft Mesh {
                    url [
                      "../meshes_lite_simple/hipRollLeft.STL"
                    ]
                  }
                }
                HingeJoint {
                  jointParameters HingeJointParameters {
                    axis 0 0 1
                    anchor 0.044 0 -0.0525
                  }
                  device [
                    RotationalMotor {
                      name "hipYaw_Left"
                      maxVelocity 8
                      minPosition -0.78
                      maxPosition 0.78
                      maxTorque 105
                    }
                    PositionSensor {
                      name "hipYaw_Left_sensor"
                    }
                  ]
                  endPoint Solid {
                    translation 0.044 0 -0.0525
                    children [
                      Shape {
                        appearance DEF thighLeft_material PBRAppearance {
                          roughness 1
                          metalness 0
                        }
                        geometry DEF thighLeft Mesh {
                          url [
                            "../meshes_lite_simple/thighLeft.STL"
                          ]
                        }
                      }
                      HingeJoint {
                        jointParameters HingeJointParameters {
                          axis 0 1 0
                          anchor 0 -0.0355 -0.369
                        }
                        device [
                          RotationalMotor {
                            name "kneePitch_Left"
                            maxVelocity 15
                            minPosition -0.09
                            maxPosition 2.4
                            maxTorque 230
                          }
                          PositionSensor {
                            name "kneePitch_Left_sensor"
                          }
                        ]
                        endPoint Solid {
                          translation 0 -0.0355 -0.369
                          rotation 0 1 0 0
                          children [
                            Shape {
                              appearance DEF shinLeft_material PBRAppearance {
                                roughness 1
                                metalness 0
                              }
                              geometry DEF shinLeft Mesh {
                                url [
                                  "../meshes_lite_simple/shinLeft.STL"
                                ]
                              }
                            }
                            HingeJoint {
                              jointParameters HingeJointParameters {
                                axis 0 1 0
                                anchor 0 0 -0.37
                              }
                              device [
                                RotationalMotor {
                                  name "anklePitch_Left"
                                  maxVelocity 20
                                  minPosition -1
                                  maxPosition 0.35
                                  maxTorque 40
                                }
                                PositionSensor {
                                  name "anklePitch_Left_sensor"
                                }
                              ]
                              endPoint Solid {
                                translation 0 0 -0.37
                                rotation 0 1 0 0
                                children [
                                  Shape {
                                    appearance DEF anklePitchLeft_material PBRAppearance {
                                      roughness 1
                                      metalness 0
                                    }
                                    geometry DEF anklePitchLeft Mesh {
                                      url [
                                        "../meshes_lite_simple/anklePitchLeft.STL"
                                      ]
                                    }
                                  }
                                  HingeJoint {
                                    jointParameters HingeJointParameters {
                                    }
                                    device [
                                      RotationalMotor {
                                        name "ankleRoll_Left"
                                        maxVelocity 20
                                        minPosition -0.3491
                                        maxPosition 0.3491
                                        maxTorque 12
                                      }
                                      PositionSensor {
                                        name "ankleRoll_Left_sensor"
                                      }
                                    ]
                                    endPoint Solid {
                                      rotation 1 0 0 0
                                      children [
                                        Shape {
                                          appearance DEF toeLeft_material PBRAppearance {
                                            baseColor 0.752941 0.752941 0.752941
                                            roughness 1
                                            metalness 0
                                          }
                                          geometry DEF toeLeft Mesh {
                                            url [
                                              "../meshes_lite_simple/toeLeft.STL"
                                            ]
                                          }
                                        }
                                      ]
                                      name "toeLeft"
                                      boundingObject Pose {
                                        translation 0.047 0 -0.05
                                        children [
                                          Box {
                                            size 0.24 0.1 0.03
                                          }
                                        ]
                                      }
                                      physics Physics {
                                        density -1
                                        mass 0.4758
                                        centerOfMass [
                                          0.037007 -2.1e-05 -0.041987
                                        ]
                                        inertiaMatrix [
                                          0.00028492 0.00152181 0.00158187
                                          1.326e-05 -0.00012023 1.43e-06
                                        ]
                                      }
                                    }
                                  }
                                ]
                                name "anklePitchLeft"
                                physics Physics {
                                  density -1
                                  mass 0.031
                                  centerOfMass [
                                    0 0 0
                                  ]
                                  inertiaMatrix [
                                    3.23e-06 3.23e-06 2.1e-06
                                    0 0 0
                                  ]
                                }
                              }
                            }
                          ]
                          name "shinLeft"
                          boundingObject Pose {
                            translation 0 0 -0.2
                            children [
                              Box {
                                size 0.08 0.06 0.3
                              }
                            ]
                          }
                          physics Physics {
                            density -1
                            mass 2.198665
                            centerOfMass [
                              -0.000809 0.000973 -0.145408
                            ]
                            inertiaMatrix [
                              0.01932815 0.01940985 0.00136828
                              -1.127e-05 0.00022012 8.606e-05
                            ]
                          }
                        }
                      }
                    ]
                    name "thighLeft"
                    physics Physics {
                      density -1
                      mass 6.647497
                      centerOfMass [
                        0.003312 -0.011125 -0.135198
                      ]
                      inertiaMatrix [
                        0.05688222 0.06217155 0.01520394
                        -0.00031813 -0.00156531 0.00531838
                      ]
                    }
                  }
                }
              ]
              name "hipRollLeft"
              physics Physics {
                density -1
                mass 1.294219
                centerOfMass [
                  0.039954 -0.000116 -0.011021
                ]
                inertiaMatrix [
                  0.00134168 0.0013707 0.00144577
                  -4.31e-06 -6.007e-05 -1.695e-05
                ]
              }
            }
          }
        ]
        name "hipPitchLeft"
        physics Physics {
          density -1
          mass 2.151248
          centerOfMass [
            -0.058182 0.058895 -0.000312
          ]
          inertiaMatrix [
            0.00385847 0.00440973 0.00508085
            -0.00094455 2.598e-05 2.828e-05
          ]
        }
      }
    }
    HingeJoint {
      jointParameters HingeJointParameters {
        axis 0 0.819149 0.57358
        anchor 0 -0.096192 -0.033241
      }
      device [
        RotationalMotor {
          name "hipPitch_Right"
          maxVelocity 15
          minPosition -2.09
          maxPosition 2.09
          maxTorque 230
        }
        PositionSensor {
          name "hipPitch_Right_sensor"
        }
      ]
      endPoint Solid {
        translation 0 -0.096192 -0.033241
        rotation 1 0 0 0.6108700000000002
        children [
          Shape {
            appearance DEF hipPitchRight_material PBRAppearance {
              roughness 1
              metalness 0
            }
            geometry DEF hipPitchRight Mesh {
              url [
                "../meshes_lite_simple/hipPitchRight.STL"
              ]
            }
          }
          HingeJoint {
            jointParameters HingeJointParameters {
              anchor -0.0255 -0.069 0
            }
            device [
              RotationalMotor {
                name "hipRoll_Right"
                maxVelocity 8
                minPosition -1.57
                maxPosition 0.78
                maxTorque 160
              }
              PositionSensor {
                name "hipRoll_Right_sensor"
              }
            ]
            endPoint Solid {
              translation -0.0255 -0.069 0
              rotation -1 0 0 0.6108700000000002
              children [
                Shape {
                  appearance DEF hipRollRight_material PBRAppearance {
                    roughness 1
                    metalness 0
                  }
                  geometry DEF hipRollRight Mesh {
                    url [
                      "../meshes_lite_simple/hipRollRight.STL"
                    ]
                  }
                }
                HingeJoint {
                  jointParameters HingeJointParameters {
                    axis 0 0 1
                    anchor 0.044 0 -0.0525
                  }
                  device [
                    RotationalMotor {
                      name "hipYaw_Right"
                      maxVelocity 8
                      minPosition -0.78
                      maxPosition 0.78
                      maxTorque 105
                    }
                    PositionSensor {
                      name "hipYaw_Right_sensor"
                    }
                  ]
                  endPoint Solid {
                    translation 0.044 0 -0.0525
                    children [
                      Shape {
                        appearance DEF thighRight_material PBRAppearance {
                          roughness 1
                          metalness 0
                        }
                        geometry DEF thighRight Mesh {
                          url [
                            "../meshes_lite_simple/thighRight.STL"
                          ]
                        }
                      }
                      HingeJoint {
                        jointParameters HingeJointParameters {
                          axis 0 1 0
                          anchor 0 0.0355 -0.369
                        }
                        device [
                          RotationalMotor {
                            name "kneePitch_Right"
                            maxVelocity 15
                            minPosition -0.09
                            maxPosition 2.4
                            maxTorque 230
                          }
                          PositionSensor {
                            name "kneePitch_Right_sensor"
                          }
                        ]
                        endPoint Solid {
                          translation 0 0.0355 -0.369
                          rotation 0 1 0 0
                          children [
                            Shape {
                              appearance DEF shinRight_material PBRAppearance {
                                roughness 1
                                metalness 0
                              }
                              geometry DEF shinRight Mesh {
                                url [
                                  "../meshes_lite_simple/shinRight.STL"
                                ]
                              }
                            }
                            HingeJoint {
                              jointParameters HingeJointParameters {
                                axis 0 1 0
                                anchor 0 0 -0.37
                              }
                              device [
                                RotationalMotor {
                                  name "anklePitch_Right"
                                  maxVelocity 20
                                  minPosition -1
                                  maxPosition 0.35
                                  maxTorque 40
                                }
                                PositionSensor {
                                  name "anklePitch_Right_sensor"
                                }
                              ]
                              endPoint Solid {
                                translation 0 0 -0.37
                                rotation 0 1 0 0
                                children [
                                  Shape {
                                    appearance DEF anklePitchRight_material PBRAppearance {
                                      baseColor 0.752941 0.752941 0.752941
                                      roughness 1
                                      metalness 0
                                    }
                                    geometry DEF anklePitchRight Mesh {
                                      url [
                                        "../meshes_lite_simple/anklePitchRight.STL"
                                      ]
                                    }
                                  }
                                  HingeJoint {
                                    jointParameters HingeJointParameters {
                                    }
                                    device [
                                      RotationalMotor {
                                        name "ankleRoll_Right"
                                        maxVelocity 20
                                        minPosition -0.3491
                                        maxPosition 0.3491
                                        maxTorque 12
                                      }
                                      PositionSensor {
                                        name "ankleRoll_Right_sensor"
                                      }
                                    ]
                                    endPoint Solid {
                                      rotation 1 0 0 0
                                      children [
                                        Shape {
                                          appearance DEF toeRight_material PBRAppearance {
                                            baseColor 0.752941 0.752941 0.752941
                                            roughness 1
                                            metalness 0
                                          }
                                          geometry DEF toeRight Mesh {
                                            url [
                                              "../meshes_lite_simple/toeRight.STL"
                                            ]
                                          }
                                        }
                                      ]
                                      name "toeRight"
                                      boundingObject Pose {
                                        translation 0.047 0 -0.05
                                        children [
                                          Box {
                                            size 0.24 0.1 0.03
                                          }
                                        ]
                                      }
                                      physics Physics {
                                        density -1
                                        mass 0.4758
                                        centerOfMass [
                                          0.037003 2.2e-05 -0.041976
                                        ]
                                        inertiaMatrix [
                                          0.00028522 0.00152191 0.00158164
                                          -1.32e-05 -0.00012034 -1.43e-06
                                        ]
                                      }
                                    }
                                  }
                                ]
                                name "anklePitchRight"
                                physics Physics {
                                  density -1
                                  mass 0.031
                                  centerOfMass [
                                    0 0 0
                                  ]
                                  inertiaMatrix [
                                    3.23e-06 3.23e-06 2.1e-06
                                    0 0 0
                                  ]
                                }
                              }
                            }
                          ]
                          name "shinRight"
                          boundingObject Pose {
                            translation 0 0 -0.2
                            children [
                              Box {
                                size 0.08 0.06 0.3
                              }
                            ]
                          }
                          physics Physics {
                            density -1
                            mass 2.208092
                            centerOfMass [
                              -0.0008 -0.000973 -0.146351
                            ]
                            inertiaMatrix [
                              0.0197983 0.0198766 0.00137192
                              1.096e-05 0.00021758 -9.064e-05
                            ]
                          }
                        }
                      }
                    ]
                    name "thighRight"
                    physics Physics {
                      density -1
                      mass 6.647545
                      centerOfMass [
                        0.003327 0.011103 -0.13529
                      ]
                      inertiaMatrix [
                        0.05714386 0.06243248 0.01517531
                        0.00030277 -0.00153883 -0.00531134
                      ]
                    }
                  }
                }
              ]
              name "hipRollRight"
              physics Physics {
                density -1
                mass 1.294228
                centerOfMass [
                  0.039882 0.000116 -0.011021
                ]
                inertiaMatrix [
                  0.0013417 0.00136997 0.00144502
                  3.79e-06 -6.269e-05 1.693e-05
                ]
              }
            }
          }
        ]
        name "hipPitchRight"
        physics Physics {
          density -1
          mass 2.151243
          centerOfMass [
            -0.058182 -0.05887 -0.00033
          ]
          inertiaMatrix [
            0.00385735 0.0044067 0.0050828
            0.0009421 2.77e-05 -2.677e-05
          ]
        }
      }
    }
  ]
  name "Adam"
  boundingObject Pose {
    rotation 1 0 0 1.57
    children [
      Cylinder {
        height 0.2
        radius 0.1
      }
    ]
  }
  physics Physics {
    density -1
    mass 10.1873
    centerOfMass [
      -0.001203 -1e-06 -0.008022
    ]
    inertiaMatrix [
      0.06839529 0.0375323 0.07519708
      -9.95e-06 -4.308e-05 -1.05e-06
    ]
  }
  controller "mpc_controller"
  supervisor TRUE
}
