#VRML_SIM R2023b utf8

EXTERNPROTO "https://raw.githubusercontent.com/cyberbotics/webots/R2023b/projects/objects/backgrounds/protos/TexturedBackground.proto"
EXTERNPROTO "https://raw.githubusercontent.com/cyberbotics/webots/R2023b/projects/objects/backgrounds/protos/TexturedBackgroundLight.proto"
EXTERNPROTO "https://raw.githubusercontent.com/cyberbotics/webots/R2023b/projects/objects/floors/protos/Floor.proto"

WorldInfo {
  basicTimeStep 1.25
}
Viewpoint {
  orientation -0.1453580887070405 0.34343019883502474 0.9278613714211686 0.8559497190239019
  position -0.636124402211119 -0.7786001771738043 0.6948095343933104
}
TexturedBackground {
}
TexturedBackgroundLight {
}
Floor {
}
DEF DuckDuck Robot {
  translation 0 0 0.4
  children [
    Pose {
      children [
        InertialUnit {
        }
        Gyro {
        }
        Accelerometer {
        }
      ]
    }
    Shape {
      appearance DEF base_material PBRAppearance {
        roughness 1
        metalness 0
      }
      geometry DEF base Mesh {
        url [
          "../meshes_DuckDuck/base.STL"
        ]
      }
    }
    HingeJoint {
      jointParameters HingeJointParameters {
        axis 0 0 1
        anchor 0 0.04 0
      }
      device [
        RotationalMotor {
          name "left_hip_yaw_joint"
          maxVelocity 15
          minPosition -2
          maxPosition 2
          maxTorque 5
        }
        PositionSensor {
          name "left_hip_yaw_joint_sensor"
        }
      ]
      endPoint Solid {
        translation 0 0.04 0
        children [
          Shape {
            appearance DEF left_hip_yaw_material PBRAppearance {
              roughness 1
              metalness 0
            }
            geometry DEF left_hip_yaw Mesh {
              url [
                "../meshes_DuckDuck/left_hip_yaw.STL"
              ]
            }
          }
          HingeJoint {
            jointParameters HingeJointParameters {
            }
            device [
              RotationalMotor {
                name "left_hip_roll_joint"
                maxVelocity 15
                minPosition -2
                maxPosition 2
                maxTorque 5
              }
              PositionSensor {
                name "left_hip_roll_joint_sensor"
              }
            ]
            endPoint Solid {
              rotation 1 0 0 0
              children [
                Shape {
                  appearance DEF left_hip_roll_material PBRAppearance {
                    roughness 1
                    metalness 0
                  }
                  geometry DEF left_hip_roll Mesh {
                    url [
                      "../meshes_DuckDuck/left_hip_roll.STL"
                    ]
                  }
                }
                HingeJoint {
                  jointParameters HingeJointParameters {
                    axis 0 1 0
                  }
                  device [
                    RotationalMotor {
                      name "left_hip_pitch_joint"
                      maxVelocity 15
                      minPosition -2
                      maxPosition 2
                      maxTorque 5
                    }
                    PositionSensor {
                      name "left_hip_pitch_joint_sensor"
                    }
                  ]
                  endPoint Solid {
                    rotation 0 1 0 0
                    children [
                      Shape {
                        appearance DEF left_hip_pitch_material PBRAppearance {
                          roughness 1
                          metalness 0
                        }
                        geometry DEF left_hip_pitch Mesh {
                          url [
                            "../meshes_DuckDuck/left_hip_pitch.STL"
                          ]
                        }
                      }
                      HingeJoint {
                        jointParameters HingeJointParameters {
                          axis 0 1 0
                          anchor 0 0.093618 -0.14
                        }
                        device [
                          RotationalMotor {
                            name "left_knee_pitch_joint"
                            maxVelocity 15
                            minPosition -2
                            maxPosition 2
                            maxTorque 5
                          }
                          PositionSensor {
                            name "left_knee_pitch_joint_sensor"
                          }
                        ]
                        endPoint Solid {
                          translation 0 0.093618 -0.14
                          rotation 0 1 0 0
                          children [
                            Shape {
                              appearance DEF left_knee_pitch_material PBRAppearance {
                                roughness 1
                                metalness 0
                              }
                              geometry DEF left_knee_pitch Mesh {
                                url [
                                  "../meshes_DuckDuck/left_knee_pitch.STL"
                                ]
                              }
                            }
                            HingeJoint {
                              jointParameters HingeJointParameters {
                                axis 0 1 0
                                anchor 0 0 -0.14
                              }
                              device [
                                RotationalMotor {
                                  name "left_ankle_pitch_joint"
                                  maxVelocity 15
                                  minPosition -2
                                  maxPosition 2
                                  maxTorque 5
                                }
                                PositionSensor {
                                  name "left_ankle_pitch_joint_sensor"
                                }
                              ]
                              endPoint Solid {
                                translation 0 0 -0.14
                                rotation 0 1 0 0
                                children [
                                  Shape {
                                    appearance DEF left_ankle_pitch_material PBRAppearance {
                                      roughness 1
                                      metalness 0
                                    }
                                    geometry DEF left_ankle_pitch Mesh {
                                      url [
                                        "../meshes_DuckDuck/left_ankle_pitch.STL"
                                      ]
                                    }
                                  }
                                  HingeJoint {
                                    jointParameters HingeJointParameters {
                                      anchor 0 0 -0.052392
                                    }
                                    device [
                                      RotationalMotor {
                                        name "left_ankle_roll_joint"
                                        maxVelocity 15
                                        minPosition -2
                                        maxPosition 2
                                        maxTorque 5
                                      }
                                      PositionSensor {
                                        name "left_ankle_roll_joint_sensor"
                                      }
                                    ]
                                    endPoint Solid {
                                      translation 0 0 -0.052392
                                      rotation 1 0 0 0
                                      children [
                                        Shape {
                                          appearance DEF left_ankle_roll_material PBRAppearance {
                                            roughness 1
                                            metalness 0
                                          }
                                          geometry DEF left_ankle_roll Mesh {
                                            url [
                                              "../meshes_DuckDuck/left_ankle_roll.STL"
                                            ]
                                          }
                                        }
                                      ]
                                      name "left_ankle_roll"
                                      boundingObject USE left_ankle_roll
                                      physics Physics {
                                        density -1
                                        mass 0.028274
                                        centerOfMass [
                                          0.015 0 0
                                        ]
                                        inertiaMatrix [
                                          1.413717e-06 1.979203e-05 1.979203e-05
                                          5.19254e-21 7.151875e-22 -6.617445e-23
                                        ]
                                      }
                                    }
                                  }
                                ]
                                name "left_ankle_pitch"
                                physics Physics {
                                  density -1
                                  mass 0.065149
                                  centerOfMass [
                                    0.017197 0.00126 -0.027458
                                  ]
                                  inertiaMatrix [
                                    2.711704e-05 0.000111641 8.940547e-05
                                    1.412297e-06 1.453432e-06 -2.232593e-06
                                  ]
                                }
                              }
                            }
                          ]
                          name "left_knee_pitch"
                          physics Physics {
                            density -1
                            mass 0.232718
                            centerOfMass [
                              0 -0.008573 -0.12701
                            ]
                            inertiaMatrix [
                              0.0002026604 0.0002498035 0.0001067836
                              5.181712e-21 -1.270358e-19 4.208279e-20
                            ]
                          }
                        }
                      }
                    ]
                    name "left_hip_pitch"
                    physics Physics {
                      density -1
                      mass 0.240239
                      centerOfMass [
                        0 0.084559 -0.125226
                      ]
                      inertiaMatrix [
                        0.0002251385 0.0002885958 0.0001231291
                        -6.017902e-22 -1.331962e-19 3.548631e-20
                      ]
                    }
                  }
                }
              ]
              name "left_hip_roll"
              physics Physics {
                density -1
                mass 0.227465
                centerOfMass [
                  0.000169 0.073254 -1.4e-05
                ]
                inertiaMatrix [
                  0.0001390617 0.0001542151 0.000132221
                  9.722037e-07 -3.277185e-09 5.578634e-08
                ]
              }
            }
          }
        ]
        name "left_hip_yaw"
        physics Physics {
          density -1
          mass 0.227707
          centerOfMass [
            -0.014842 -1.4e-05 0.005181
          ]
          inertiaMatrix [
            0.0001606459 0.0001228832 0.000114845
            -1.058444e-08 2.794947e-06 5.011805e-08
          ]
        }
      }
    }
    HingeJoint {
      jointParameters HingeJointParameters {
        axis 0 0 -1
        anchor 0 -0.04 0
      }
      device [
        RotationalMotor {
          name "right_hip_yaw_joint"
          maxVelocity 15
          minPosition -2
          maxPosition 2
          maxTorque 5
        }
        PositionSensor {
          name "right_hip_yaw_joint_sensor"
        }
      ]
      endPoint Solid {
        translation 0 -0.04 0
        rotation 0 0 -1 0
        children [
          Shape {
            appearance DEF right_hip_yaw_material PBRAppearance {
              roughness 1
              metalness 0
            }
            geometry DEF right_hip_yaw Mesh {
              url [
                "../meshes_DuckDuck/right_hip_yaw.STL"
              ]
            }
          }
          HingeJoint {
            jointParameters HingeJointParameters {
              axis -1 0 0
            }
            device [
              RotationalMotor {
                name "right_hip_roll_joint"
                maxVelocity 15
                minPosition -2
                maxPosition 2
                maxTorque 5
              }
              PositionSensor {
                name "right_hip_roll_joint_sensor"
              }
            ]
            endPoint Solid {
              rotation -1 0 0 0
              children [
                Shape {
                  appearance DEF right_hip_roll_material PBRAppearance {
                    roughness 1
                    metalness 0
                  }
                  geometry DEF right_hip_roll Mesh {
                    url [
                      "../meshes_DuckDuck/right_hip_roll.STL"
                    ]
                  }
                }
                HingeJoint {
                  jointParameters HingeJointParameters {
                    axis 0 1 0
                  }
                  device [
                    RotationalMotor {
                      name "right_hip_pitch_joint"
                      maxVelocity 15
                      minPosition -2
                      maxPosition 2
                      maxTorque 5
                    }
                    PositionSensor {
                      name "right_hip_pitch_joint_sensor"
                    }
                  ]
                  endPoint Solid {
                    rotation 0 1 0 0
                    children [
                      Shape {
                        appearance DEF right_hip_pitch_material PBRAppearance {
                          roughness 1
                          metalness 0
                        }
                        geometry DEF right_hip_pitch Mesh {
                          url [
                            "../meshes_DuckDuck/right_hip_pitch.STL"
                          ]
                        }
                      }
                      HingeJoint {
                        jointParameters HingeJointParameters {
                          axis 0 1 0
                          anchor 0 -0.093618 -0.14
                        }
                        device [
                          RotationalMotor {
                            name "right_knee_pitch_joint"
                            maxVelocity 15
                            minPosition -2
                            maxPosition 2
                            maxTorque 5
                          }
                          PositionSensor {
                            name "right_knee_pitch_joint_sensor"
                          }
                        ]
                        endPoint Solid {
                          translation 0 -0.093618 -0.14
                          rotation 0 1 0 0
                          children [
                            Shape {
                              appearance DEF right_knee_pitch_material PBRAppearance {
                                roughness 1
                                metalness 0
                              }
                              geometry DEF right_knee_pitch Mesh {
                                url [
                                  "../meshes_DuckDuck/right_knee_pitch.STL"
                                ]
                              }
                            }
                            HingeJoint {
                              jointParameters HingeJointParameters {
                                axis 0 1 0
                                anchor 0 0 -0.14
                              }
                              device [
                                RotationalMotor {
                                  name "right_ankle_pitch_joint"
                                  maxVelocity 15
                                  minPosition -2
                                  maxPosition 2
                                  maxTorque 5
                                }
                                PositionSensor {
                                  name "right_ankle_pitch_joint_sensor"
                                }
                              ]
                              endPoint Solid {
                                translation 0 0 -0.14
                                rotation 0 1 0 0
                                children [
                                  Shape {
                                    appearance DEF right_ankle_pitch_material PBRAppearance {
                                      roughness 1
                                      metalness 0
                                    }
                                    geometry DEF right_ankle_pitch Mesh {
                                      url [
                                        "../meshes_DuckDuck/right_ankle_pitch.STL"
                                      ]
                                    }
                                  }
                                  HingeJoint {
                                    jointParameters HingeJointParameters {
                                      axis -1 0 0
                                      anchor 0 0 -0.052392
                                    }
                                    device [
                                      RotationalMotor {
                                        name "right_ankle_roll_joint"
                                        maxVelocity 15
                                        minPosition -2
                                        maxPosition 2
                                        maxTorque 5
                                      }
                                      PositionSensor {
                                        name "right_ankle_roll_joint_sensor"
                                      }
                                    ]
                                    endPoint Solid {
                                      translation 0 0 -0.052392
                                      rotation -1 0 0 0
                                      children [
                                        Shape {
                                          appearance DEF right_ankle_roll_material PBRAppearance {
                                            roughness 1
                                            metalness 0
                                          }
                                          geometry DEF right_ankle_roll Mesh {
                                            url [
                                              "../meshes_DuckDuck/right_ankle_roll.STL"
                                            ]
                                          }
                                        }
                                      ]
                                      name "right_ankle_roll"
                                      boundingObject USE right_ankle_roll
                                      physics Physics {
                                        density -1
                                        mass 0.028274
                                        centerOfMass [
                                          0.015 0 0
                                        ]
                                        inertiaMatrix [
                                          1.413717e-06 1.979203e-05 1.979203e-05
                                          6.224734e-22 8.051978e-23 -7.858216e-24
                                        ]
                                      }
                                    }
                                  }
                                ]
                                name "right_ankle_pitch"
                                physics Physics {
                                  density -1
                                  mass 0.065149
                                  centerOfMass [
                                    0.017197 -0.00126 -0.027458
                                  ]
                                  inertiaMatrix [
                                    2.71171e-05 0.0001116411 8.940551e-05
                                    -1.412304e-06 1.453334e-06 2.232571e-06
                                  ]
                                }
                              }
                            }
                          ]
                          name "right_knee_pitch"
                          physics Physics {
                            density -1
                            mass 0.232718
                            centerOfMass [
                              0 0.008573 -0.12701
                            ]
                            inertiaMatrix [
                              0.0002026604 0.0002498035 0.0001067836
                              -3.425814e-20 -1.551707e-19 2.64884e-20
                            ]
                          }
                        }
                      }
                    ]
                    name "right_hip_pitch"
                    physics Physics {
                      density -1
                      mass 0.240239
                      centerOfMass [
                        0 -0.084559 -0.125226
                      ]
                      inertiaMatrix [
                        0.0002251385 0.0002885958 0.0001231291
                        -5.104574e-20 -1.640381e-19 -2.387429e-20
                      ]
                    }
                  }
                }
              ]
              name "right_hip_roll"
              physics Physics {
                density -1
                mass 0.227465
                centerOfMass [
                  0.000169 -0.073254 1.4e-05
                ]
                inertiaMatrix [
                  0.0001390617 0.0001542151 0.000132221
                  -9.722037e-07 3.277185e-09 5.578634e-08
                ]
              }
            }
          }
        ]
        name "right_hip_yaw"
        physics Physics {
          density -1
          mass 0.227707
          centerOfMass [
            -0.014842 -1.4e-05 0.005181
          ]
          inertiaMatrix [
            0.0001606459 0.0001228832 0.000114845
            -1.058444e-08 2.794947e-06 5.011805e-08
          ]
        }
      }
    }
    HingeJoint {
      jointParameters HingeJointParameters {
        axis 0 1 0
        anchor 0.0775 0 0.108875
      }
      device [
        RotationalMotor {
          name "throat_pitch_joint"
          maxVelocity 15
          minPosition -2
          maxPosition 2
          maxTorque 5
        }
        PositionSensor {
          name "throat_pitch_joint_sensor"
        }
      ]
      endPoint Solid {
        translation 0.0775 0 0.108875
        rotation 0 1 0 0
        children [
          Shape {
            appearance DEF throat_pitch_material PBRAppearance {
              roughness 1
              metalness 0
            }
            geometry DEF throat_pitch Mesh {
              url [
                "../meshes_DuckDuck/throat_pitch.STL"
              ]
            }
          }
          HingeJoint {
            jointParameters HingeJointParameters {
              axis -1 0 0
              anchor 0 -0.0025 0.0775
            }
            device [
              RotationalMotor {
                name "throat_roll_joint"
                maxVelocity 15
                minPosition -2
                maxPosition 2
                maxTorque 5
              }
              PositionSensor {
                name "throat_roll_joint_sensor"
              }
            ]
            endPoint Solid {
              translation 0 -0.0025 0.0775
              rotation -1 0 0 0
              children [
                Shape {
                  appearance DEF throat_roll_material PBRAppearance {
                    roughness 1
                    metalness 0
                  }
                  geometry DEF throat_roll Mesh {
                    url [
                      "../meshes_DuckDuck/throat_roll.STL"
                    ]
                  }
                }
                HingeJoint {
                  jointParameters HingeJointParameters {
                    axis 0 0 1
                    anchor 0 0 0.061
                  }
                  device [
                    RotationalMotor {
                      name "throat_yaw_joint"
                      maxVelocity 15
                      minPosition -2
                      maxPosition 2
                      maxTorque 5
                    }
                    PositionSensor {
                      name "throat_yaw_joint_sensor"
                    }
                  ]
                  endPoint Solid {
                    translation 0 0 0.061
                    children [
                      Shape {
                        appearance DEF throat_yaw_material PBRAppearance {
                          roughness 1
                          metalness 0
                        }
                        geometry DEF throat_yaw Mesh {
                          url [
                            "../meshes_DuckDuck/throat_yaw.STL"
                          ]
                        }
                      }
                    ]
                    name "throat_yaw"
                    physics Physics {
                      density -1
                      mass 1.364893
                      centerOfMass [
                        -0.006017 0 0.024297
                      ]
                      inertiaMatrix [
                        0.002646118 0.004587562 0.006711535
                        -7.567283e-18 -6.370955e-05 5.466259e-19
                      ]
                    }
                  }
                }
              ]
              name "throat_roll"
              physics Physics {
                density -1
                mass 0.05549
                centerOfMass [
                  0 0 0.025398
                ]
                inertiaMatrix [
                  3.521556e-05 2.952544e-05 9.347601e-06
                  1.775336e-20 -3.682257e-20 -6.881555e-21
                ]
              }
            }
          }
        ]
        name "throat_pitch"
        physics Physics {
          density -1
          mass 0.094414
          centerOfMass [
            0 -0.0025 0.050093
          ]
          inertiaMatrix [
            5.982277e-05 5.752288e-05 3.405908e-05
            8.625328e-21 -3.224557e-20 -1.136273e-20
          ]
        }
      }
    }
  ]
  name "DuckDuck"
  physics Physics {
    density -1
    mass 1.700374
    centerOfMass [
      -0.010093 -8.5e-05 0.041711
    ]
    inertiaMatrix [
      0.01102631 0.01721595 0.01518094
      1.156032e-08 0.0001853957 -8.115702e-09
    ]
  }
  controller "mpc_controller"
  supervisor TRUE
}
