<?xml version="1.0" encoding="utf-8"?>
<!-- This URDF was automatically created by SolidWorks to URDF Exporter! Originally created by Stephen Brawner (brawner@gmail.com) 
     Commit Version: 1.6.0-4-g7f85cfe  Build Version: 1.6.7995.38578
     For more information, please see http://wiki.ros.org/sw_urdf_exporter -->
<robot name="DuckDuck">
  <link name="world"/>
  <joint name="floating_joint" type="floating">
    <parent link="world"/>
    <child link="base"/>
    <origin xyz="0 0 0" rpy="0 0 0"/>
    <axis xyz="0 0 0 1 0 0" />
    <axis xyz="0 0 0 0 1 0" />
    <axis xyz="0 0 0 0 0 1" />
    <axis xyz="1 0 0" />
    <axis xyz="0 1 0" />
    <axis xyz="0 0 1" />
  </joint>
  <link name="base">
    <inertial>
      <origin xyz="-0.0100928530626795 -8.48766786223073E-05 0.0417109438407734" rpy="0 0 0" />
      <mass value="1.70037419863104" />
      <inertia ixx="0.011026305690898" ixy="1.15603196804474E-08" ixz="0.000185395732857203" iyy="0.0172159470283866" iyz="-8.11570230276946E-09" izz="0.0151809445338661" />
    </inertial>
    <visual>
      <origin xyz="0 0 0" rpy="0 0 0" />
      <geometry>
        <mesh filename="../meshes/base.STL" />
      </geometry>
      <material name="">
        <color rgba="1 1 1 1" />
      </material>
    </visual>
    <collision>
      <origin xyz="0 0 0" rpy="0 0 0" />
      <geometry>
        <mesh filename="../meshes/base.STL" />
      </geometry>
    </collision>
  </link>
  <link name="left_hip_yaw">
    <inertial>
      <origin xyz="-0.0148415027804522 -1.42278207789504E-05 0.00518098759586325" rpy="0 0 0" />
      <mass value="0.22770651071542" />
      <inertia ixx="0.00016064594987398" ixy="-1.0584438013289E-08" ixz="2.79494697437766E-06" iyy="0.000122883197379238" iyz="5.01180502056784E-08" izz="0.000114845036646105" />
    </inertial>
    <visual>
      <origin xyz="0 0 0" rpy="0 0 0" />
      <geometry>
        <mesh filename="../meshes/left_hip_yaw.STL" />
      </geometry>
      <material name="">
        <color rgba="1 1 1 1" />
      </material>
    </visual>
    <collision>
      <origin xyz="0 0 0" rpy="0 0 0" />
      <geometry>
        <mesh filename="../meshes/left_hip_yaw.STL" />
      </geometry>
    </collision>
  </link>
  <joint name="left_hip_yaw_joint" type="revolute">
    <origin xyz="0 0.04 0" rpy="0 0 0" />
    <parent link="base" />
    <child link="left_hip_yaw" />
    <axis xyz="0 0 1" />
    <limit lower="-2" upper="2" effort="20" velocity="15.0" />
  </joint>
  <link name="left_hip_roll">
    <inertial>
      <origin xyz="0.00016868655630813 0.0732538542750924 -1.42428991139337E-05" rpy="0 0 0" />
      <mass value="0.22746544778837" />
      <inertia ixx="0.000139061664775468" ixy="9.72203682012463E-07" ixz="-3.27718468280282E-09" iyy="0.000154215112847962" iyz="5.57863354309902E-08" izz="0.000132221036670331" />
    </inertial>
    <visual>
      <origin xyz="0 0 0" rpy="0 0 0" />
      <geometry>
        <mesh filename="../meshes/left_hip_roll.STL" />
      </geometry>
      <material name="">
        <color rgba="1 1 1 1" />
      </material>
    </visual>
    <collision>
      <origin xyz="0 0 0" rpy="0 0 0" />
      <geometry>
        <mesh filename="../meshes/left_hip_roll.STL" />
      </geometry>
    </collision>
  </link>
  <joint name="left_hip_roll_joint" type="revolute">
    <origin xyz="0 0 0" rpy="0 0 0" />
    <parent link="left_hip_yaw" />
    <child link="left_hip_roll" />
    <axis xyz="1 0 0" />
    <limit lower="-2" upper="2" effort="20" velocity="15.0" />
  </joint>
  <link name="left_hip_pitch">
    <inertial>
      <origin xyz="-3.35688425254106E-16 0.0845594117245176 -0.125225619873394" rpy="0 0 0" />
      <mass value="0.24023854356995" />
      <inertia ixx="0.000225138484662056" ixy="-6.01790208528758E-22" ixz="-1.33196195508682E-19" iyy="0.000288595828376715" iyz="3.54863128273055E-20" izz="0.000123129101652142" />
    </inertial>
    <visual>
      <origin xyz="0 0 0" rpy="0 0 0" />
      <geometry>
        <mesh filename="../meshes/left_hip_pitch.STL" />
      </geometry>
      <material name="">
        <color rgba="1 1 1 1" />
      </material>
    </visual>
    <collision>
      <origin xyz="0 0 0" rpy="0 0 0" />
      <geometry>
        <mesh filename="../meshes/left_hip_pitch.STL" />
      </geometry>
    </collision>
  </link>
  <joint name="left_hip_pitch_joint" type="revolute">
    <origin xyz="0 0 0" rpy="0 0 0" />
    <parent link="left_hip_roll" />
    <child link="left_hip_pitch" />
    <axis xyz="0 1 0" />
    <limit lower="-2" upper="2" effort="20" velocity="15.0" />
  </joint>
  <link name="left_knee_pitch">
    <inertial>
      <origin xyz="-3.14931093635428E-16 -0.00857325265941741 -0.127010278601144" rpy="0 0 0" />
      <mass value="0.232718078417979" />
      <inertia ixx="0.000202660360914128" ixy="5.18171181382048E-21" ixz="-1.27035811917264E-19" iyy="0.000249803523853592" iyz="4.20827856752809E-20" izz="0.000106783585605482" />
    </inertial>
    <visual>
      <origin xyz="0 0 0" rpy="0 0 0" />
      <geometry>
        <mesh filename="../meshes/left_knee_pitch.STL" />
      </geometry>
      <material name="">
        <color rgba="1 1 1 1" />
      </material>
    </visual>
    <collision>
      <origin xyz="0 0 0" rpy="0 0 0" />
      <geometry>
        <mesh filename="../meshes/left_knee_pitch.STL" />
      </geometry>
    </collision>
  </link>
  <joint name="left_knee_pitch_joint" type="revolute">
    <origin xyz="0 0.0936181760425075 -0.14" rpy="0 0 0" />
    <parent link="left_hip_pitch" />
    <child link="left_knee_pitch" />
    <axis xyz="0 1 0" />
    <limit lower="-2" upper="2" effort="20" velocity="15.0" />
  </joint>
  <link name="left_ankle_pitch">
    <inertial>
      <origin xyz="0.0171971119634686 0.00125991692727168 -0.027457582228249" rpy="0 0 0" />
      <mass value="0.0651489641090865" />
      <inertia ixx="2.71170426483944E-05" ixy="1.41229735589195E-06" ixz="1.45343243518079E-06" iyy="0.000111640995669254" iyz="-2.23259273055197E-06" izz="8.94054733742727E-05" />
    </inertial>
    <visual>
      <origin xyz="0 0 0" rpy="0 0 0" />
      <geometry>
        <mesh filename="../meshes/left_ankle_pitch.STL" />
      </geometry>
      <material name="">
        <color rgba="1 1 1 1" />
      </material>
    </visual>
    <collision>
      <origin xyz="0 0 0" rpy="0 0 0" />
      <geometry>
        <mesh filename="../meshes/left_ankle_pitch.STL" />
      </geometry>
    </collision>
  </link>
  <joint name="left_ankle_pitch_joint" type="revolute">
    <origin xyz="0 0 -0.14" rpy="0 0 0" />
    <parent link="left_knee_pitch" />
    <child link="left_ankle_pitch" />
    <axis xyz="0 1 0" />
    <limit lower="-2" upper="2" effort="20" velocity="15.0" />
  </joint>
  <link name="left_ankle_roll">
    <inertial>
      <origin xyz="0.0149999999999993 -2.77555756156289E-17 -4.94049245958195E-15" rpy="0 0 0" />
      <mass value="0.0282743338823081" />
      <inertia ixx="1.41371669411541E-06" ixy="5.1925397296605E-21" ixz="7.15187474625493E-22" iyy="1.97920337176157E-05" iyz="-6.61744490042407E-23" izz="1.97920337176157E-05" />
    </inertial>
    <visual>
      <origin xyz="0 0 0" rpy="0 0 0" />
      <geometry>
        <mesh filename="../meshes/left_ankle_roll.STL" />
      </geometry>
      <material name="">
        <color rgba="1 1 1 1" />
      </material>
    </visual>
    <collision>
      <origin xyz="0 0 0" rpy="0 0 0" />
      <geometry>
        <mesh filename="../meshes/left_ankle_roll.STL" />
      </geometry>
    </collision>
  </link>
  <joint name="left_ankle_roll_joint" type="revolute">
    <origin xyz="0 0 -0.0523924267994756" rpy="0 0 0" />
    <parent link="left_ankle_pitch" />
    <child link="left_ankle_roll" />
    <axis xyz="1 0 0" />
    <limit lower="-2" upper="2" effort="20" velocity="15.0" />
  </joint>
  <link name="right_hip_yaw">
    <inertial>
      <origin xyz="-0.0148415027804522 -1.4227820776147E-05 0.00518098759586436" rpy="0 0 0" />
      <mass value="0.22770651071542" />
      <inertia ixx="0.00016064594987398" ixy="-1.05844380133239E-08" ixz="2.7949469743776E-06" iyy="0.000122883197379238" iyz="5.01180502056588E-08" izz="0.000114845036646105" />
    </inertial>
    <visual>
      <origin xyz="0 0 0" rpy="0 0 0" />
      <geometry>
        <mesh filename="../meshes/right_hip_yaw.STL" />
      </geometry>
      <material name="">
        <color rgba="1 1 1 1" />
      </material>
    </visual>
    <collision>
      <origin xyz="0 0 0" rpy="0 0 0" />
      <geometry>
        <mesh filename="../meshes/right_hip_yaw.STL" />
      </geometry>
    </collision>
  </link>
  <joint name="right_hip_yaw_joint" type="revolute">
    <origin xyz="0 -0.04 0" rpy="0 0 0" />
    <parent link="base" />
    <child link="right_hip_yaw" />
    <axis xyz="0 0 -1" />
    <limit lower="-2" upper="2" effort="20" velocity="15.0" />
  </joint>
  <link name="right_hip_roll">
    <inertial>
      <origin xyz="0.000168686556307084 -0.073253854275096 1.42428991107002E-05" rpy="0 0 0" />
      <mass value="0.22746544778837" />
      <inertia ixx="0.000139061664775468" ixy="-9.72203682012507E-07" ixz="3.27718468277951E-09" iyy="0.000154215112847962" iyz="5.57863354310647E-08" izz="0.000132221036670331" />
    </inertial>
    <visual>
      <origin xyz="0 0 0" rpy="0 0 0" />
      <geometry>
        <mesh filename="../meshes/right_hip_roll.STL" />
      </geometry>
      <material name="">
        <color rgba="1 1 1 1" />
      </material>
    </visual>
    <collision>
      <origin xyz="0 0 0" rpy="0 0 0" />
      <geometry>
        <mesh filename="../meshes/right_hip_roll.STL" />
      </geometry>
    </collision>
  </link>
  <joint name="right_hip_roll_joint" type="revolute">
    <origin xyz="0 0 0" rpy="0 0 0" />
    <parent link="right_hip_yaw" />
    <child link="right_hip_roll" />
    <axis xyz="-1 0 0" />
    <limit lower="-2" upper="2" effort="20" velocity="15.0" />
  </joint>
  <link name="right_hip_pitch">
    <inertial>
      <origin xyz="9.8250059966117E-17 -0.0845594117245176 -0.125225619873394" rpy="0 0 0" />
      <mass value="0.24023854356995" />
      <inertia ixx="0.000225138484662056" ixy="-5.10457369633909E-20" ixz="-1.64038087116657E-19" iyy="0.000288595828376715" iyz="-2.38742900383508E-20" izz="0.000123129101652142" />
    </inertial>
    <visual>
      <origin xyz="0 0 0" rpy="0 0 0" />
      <geometry>
        <mesh filename="../meshes/right_hip_pitch.STL" />
      </geometry>
      <material name="">
        <color rgba="1 1 1 1" />
      </material>
    </visual>
    <collision>
      <origin xyz="0 0 0" rpy="0 0 0" />
      <geometry>
        <mesh filename="../meshes/right_hip_pitch.STL" />
      </geometry>
    </collision>
  </link>
  <joint name="right_hip_pitch_joint" type="revolute">
    <origin xyz="0 0 0" rpy="0 0 0" />
    <parent link="right_hip_roll" />
    <child link="right_hip_pitch" />
    <axis xyz="0 1 0" />
    <limit lower="-2" upper="2" effort="20" velocity="15.0" />
  </joint>
  <link name="right_knee_pitch">
    <inertial>
      <origin xyz="-1.85705319768296E-16 0.00857325265941841 -0.127010278601144" rpy="0 0 0" />
      <mass value="0.232718078417978" />
      <inertia ixx="0.000202660360914127" ixy="-3.42581386582497E-20" ixz="-1.55170653183977E-19" iyy="0.000249803523853592" iyz="2.64883998539048E-20" izz="0.000106783585605481" />
    </inertial>
    <visual>
      <origin xyz="0 0 0" rpy="0 0 0" />
      <geometry>
        <mesh filename="../meshes/right_knee_pitch.STL" />
      </geometry>
      <material name="">
        <color rgba="1 1 1 1" />
      </material>
    </visual>
    <collision>
      <origin xyz="0 0 0" rpy="0 0 0" />
      <geometry>
        <mesh filename="../meshes/right_knee_pitch.STL" />
      </geometry>
    </collision>
  </link>
  <joint name="right_knee_pitch_joint" type="revolute">
    <origin xyz="0 -0.0936181760425084 -0.14" rpy="0 0 0" />
    <parent link="right_hip_pitch" />
    <child link="right_knee_pitch" />
    <axis xyz="0 1 0" />
    <limit lower="-2" upper="2" effort="20" velocity="15.0" />
  </joint>
  <link name="right_ankle_pitch">
    <inertial>
      <origin xyz="0.0171970814557113 -0.00125992066950759 -0.0274576170413897" rpy="0 0 0" />
      <mass value="0.0651490178313245" />
      <inertia ixx="2.71171025823446E-05" ixy="-1.41230393207431E-06" ixz="1.45333365120518E-06" iyy="0.000111641093323312" iyz="2.23257104497736E-06" izz="8.94055118440263E-05" />
    </inertial>
    <visual>
      <origin xyz="0 0 0" rpy="0 0 0" />
      <geometry>
        <mesh filename="../meshes/right_ankle_pitch.STL" />
      </geometry>
      <material name="">
        <color rgba="1 1 1 1" />
      </material>
    </visual>
    <collision>
      <origin xyz="0 0 0" rpy="0 0 0" />
      <geometry>
        <mesh filename="../meshes/right_ankle_pitch.STL" />
      </geometry>
    </collision>
  </link>
  <joint name="right_ankle_pitch_joint" type="revolute">
    <origin xyz="0 0 -0.14" rpy="0 0 0" />
    <parent link="right_knee_pitch" />
    <child link="right_ankle_pitch" />
    <axis xyz="0 1 0" />
    <limit lower="-2" upper="2" effort="20" velocity="15.0" />
  </joint>
  <link name="right_ankle_roll">
    <inertial>
      <origin xyz="0.0149999999999999 -1.33226762955019E-15 5.55111512312578E-16" rpy="0 0 0" />
      <mass value="0.0282743338823081" />
      <inertia ixx="1.41371669411541E-06" ixy="6.2247337944344E-22" ixz="8.05197805008483E-23" iyy="1.97920337176157E-05" iyz="-7.85821581925374E-24" izz="1.97920337176157E-05" />
    </inertial>
    <visual>
      <origin xyz="0 0 0" rpy="0 0 0" />
      <geometry>
        <mesh filename="../meshes/right_ankle_roll.STL" />
      </geometry>
      <material name="">
        <color rgba="1 1 1 1" />
      </material>
    </visual>
    <collision>
      <origin xyz="0 0 0" rpy="0 0 0" />
      <geometry>
        <mesh filename="../meshes/right_ankle_roll.STL" />
      </geometry>
    </collision>
  </link>
  <joint name="right_ankle_roll_joint" type="revolute">
    <origin xyz="0 0 -0.0523924267994828" rpy="0 0 0" />
    <parent link="right_ankle_pitch" />
    <child link="right_ankle_roll" />
    <axis xyz="-1 0 0" />
    <limit lower="-2" upper="2" effort="20" velocity="15.0" />
  </joint>
  <link name="neck_pitch">
    <inertial>
      <origin xyz="2.22044604925031E-16 -0.00249999999999993 0.0500927287975886" rpy="0 0 0" />
      <mass value="0.0944141515929346" />
      <inertia ixx="5.98227661229977E-05" ixy="8.62532755251327E-21" ixz="-3.22455725258216E-20" iyy="5.75228750179582E-05" iyz="-1.1362726639035E-20" izz="3.40590799851078E-05" />
    </inertial>
    <visual>
      <origin xyz="0 0 0" rpy="0 0 0" />
      <geometry>
        <mesh filename="../meshes/neck_pitch.STL" />
      </geometry>
      <material name="">
        <color rgba="1 1 1 1" />
      </material>
    </visual>
    <collision>
      <origin xyz="0 0 0" rpy="0 0 0" />
      <geometry>
        <mesh filename="../meshes/neck_pitch.STL" />
      </geometry>
    </collision>
  </link>
  <joint name="neck_pitch_joint" type="revolute">
    <origin xyz="0.0774999999999999 0 0.108874586088177" rpy="0 0 0" />
    <parent link="base" />
    <child link="neck_pitch" />
    <axis xyz="0 1 0" />
    <limit lower="-2" upper="2" effort="20" velocity="15.0" />
  </joint>
  <link name="neck_roll">
    <inertial>
      <origin xyz="4.16333634234434E-17 9.97465998686664E-18 0.025398197821265" rpy="0 0 0" />
      <mass value="0.0554895568861581" />
      <inertia ixx="3.52155621202351E-05" ixy="1.77533649293486E-20" ixz="-3.68225674531131E-20" iyy="2.9525444201718E-05" iyz="-6.88155523420156E-21" izz="9.34760082952307E-06" />
    </inertial>
    <visual>
      <origin xyz="0 0 0" rpy="0 0 0" />
      <geometry>
        <mesh filename="../meshes/neck_roll.STL" />
      </geometry>
      <material name="">
        <color rgba="1 1 1 1" />
      </material>
    </visual>
    <collision>
      <origin xyz="0 0 0" rpy="0 0 0" />
      <geometry>
        <mesh filename="../meshes/neck_roll.STL" />
      </geometry>
    </collision>
  </link>
  <joint name="neck_roll_joint" type="revolute">
    <origin xyz="0 -0.00249999999999992 0.0774999999999998" rpy="0 0 0" />
    <parent link="neck_pitch" />
    <child link="neck_roll" />
    <axis xyz="-1 0 0" />
    <limit lower="-2" upper="2" effort="20" velocity="15.0" />
  </joint>
  <link name="neck_yaw">
    <inertial>
      <origin xyz="-0.00601691442032241 1.0842021724855E-17 0.0242972736541135" rpy="0 0 0" />
      <mass value="1.36489294645362" />
      <inertia ixx="0.00264611796494262" ixy="-7.56728326507061E-18" ixz="-6.37095515701378E-05" iyy="0.00458756210789547" iyz="5.46625917605381E-19" izz="0.00671153515827188" />
    </inertial>
    <visual>
      <origin xyz="0 0 0" rpy="0 0 0" />
      <geometry>
        <mesh filename="../meshes/neck_yaw.STL" />
      </geometry>
      <material name="">
        <color rgba="1 1 1 1" />
      </material>
    </visual>
    <collision>
      <origin xyz="0 0 0" rpy="0 0 0" />
      <geometry>
        <mesh filename="../meshes/neck_yaw.STL" />
      </geometry>
    </collision>
  </link>
  <joint name="neck_yaw_joint" type="revolute">
    <origin xyz="0 0 0.061" rpy="0 0 0" />
    <parent link="neck_roll" />
    <child link="neck_yaw" />
    <axis xyz="0 0 1" />
    <limit lower="-2" upper="2" effort="20" velocity="15.0" />
  </joint>
</robot>