<?xml version="1.0" encoding="utf-8"?>
<!-- This URDF was automatically created by SolidWorks to URDF Exporter! Originally created by Stephen Brawner (brawner@gmail.com) 
     Commit Version: 1.6.0-4-g7f85cfe  Build Version: 1.6.7995.38578
     For more information, please see http://wiki.ros.org/sw_urdf_exporter -->
<robot
  name="DuckDuck">
  <link name="world"/>
  <joint name="floating_joint" type="floating">
    <parent link="world"/> 
    <child link="base"/>
    <origin xyz="0 0 0" rpy="0 0 0"/>
    <axis xyz="0 0 0 1 0 0" />
    <axis xyz="0 0 0 0 1 0" />
    <axis xyz="0 0 0 0 0 1" />
    <axis xyz="1 0 0" />
    <axis xyz="0 1 0" />
    <axis xyz="0 0 1" />
  </joint>
  <link
    name="base">
    <inertial>
      <origin
        xyz="-0.0100928530626795 -8.48766786223145E-05 0.0417109438407734"
        rpy="0 0 0" />
      <mass
        value="1.70037419863104" />
      <inertia
        ixx="0.011026305690898"
        ixy="1.15603196843698E-08"
        ixz="0.000185395732857202"
        iyy="0.0172159470283866"
        iyz="-8.11570230509126E-09"
        izz="0.0151809445338661" />
    </inertial>
    <visual>
      <origin
        xyz="0 0 0"
        rpy="0 0 0" />
      <geometry>
        <mesh
          filename="../meshes/base.STL" />
      </geometry>
      <material
        name="">
        <color
          rgba="1 1 1 1" />
      </material>
    </visual>
    <collision>
      <origin
        xyz="0 0 0"
        rpy="0 0 0" />
      <geometry>
        <mesh
          filename="../meshes/base.STL" />
      </geometry>
    </collision>
  </link>
  <link
    name="left_hip_yaw">
    <inertial>
      <origin
        xyz="-0.0148415027804522 -1.42278207764107E-05 0.00518098759586441"
        rpy="0 0 0" />
      <mass
        value="0.22770651071542" />
      <inertia
        ixx="0.00016064594987398"
        ixy="-1.05844380132887E-08"
        ixz="2.79494697437767E-06"
        iyy="0.000122883197379238"
        iyz="5.01180502056565E-08"
        izz="0.000114845036646105" />
    </inertial>
    <visual>
      <origin
        xyz="0 0 0"
        rpy="0 0 0" />
      <geometry>
        <mesh
          filename="../meshes/left_hip_yaw.STL" />
      </geometry>
      <material
        name="">
        <color
          rgba="1 1 1 1" />
      </material>
    </visual>
    <collision>
      <origin
        xyz="0 0 0"
        rpy="0 0 0" />
      <geometry>
        <mesh
          filename="../meshes/left_hip_yaw.STL" />
      </geometry>
    </collision>
  </link>
  <joint
    name="left_hip_yaw_joint"
    type="revolute">
    <origin
      xyz="0 0.04 0"
      rpy="0 0 0" />
    <parent
      link="base" />
    <child
      link="left_hip_yaw" />
    <axis
      xyz="0 0 1" />
    <limit
      lower="0"
      upper="0"
      effort="0"
      velocity="0" />
  </joint>
  <link
    name="left_hip_roll">
    <inertial>
      <origin
        xyz="0.000168686556307626 0.0732538542750958 -1.42428991109084E-05"
        rpy="0 0 0" />
      <mass
        value="0.22746544778837" />
      <inertia
        ixx="0.000139061664775468"
        ixy="9.72203682012484E-07"
        ixz="-3.27718468280349E-09"
        iyy="0.000154215112847962"
        iyz="5.578633543099E-08"
        izz="0.000132221036670331" />
    </inertial>
    <visual>
      <origin
        xyz="0 0 0"
        rpy="0 0 0" />
      <geometry>
        <mesh
          filename="../meshes/left_hip_roll.STL" />
      </geometry>
      <material
        name="">
        <color
          rgba="1 1 1 1" />
      </material>
    </visual>
    <collision>
      <origin
        xyz="0 0 0"
        rpy="0 0 0" />
      <geometry>
        <mesh
          filename="../meshes/left_hip_roll.STL" />
      </geometry>
    </collision>
  </link>
  <joint
    name="left_hip_roll_joint"
    type="revolute">
    <origin
      xyz="0 0 0"
      rpy="0 0 0" />
    <parent
      link="left_hip_yaw" />
    <child
      link="left_hip_roll" />
    <axis
      xyz="1 0 0" />
    <limit
      lower="0"
      upper="0"
      effort="0"
      velocity="0" />
  </joint>
  <link
    name="left_hip_pitch">
    <inertial>
      <origin
        xyz="-2.1854845288882E-16 0.0845594117245168 -0.125225619873394"
        rpy="0 0 0" />
      <mass
        value="0.24023854356995" />
      <inertia
        ixx="0.000225138484662056"
        ixy="9.53108124210592E-22"
        ixz="-1.34600092260421E-19"
        iyy="0.000288595828376715"
        iyz="3.53759497379051E-20"
        izz="0.000123129101652142" />
    </inertial>
    <visual>
      <origin
        xyz="0 0 0"
        rpy="0 0 0" />
      <geometry>
        <mesh
          filename="../meshes/left_hip_pitch.STL" />
      </geometry>
      <material
        name="">
        <color
          rgba="1 1 1 1" />
      </material>
    </visual>
    <collision>
      <origin
        xyz="0 0 0"
        rpy="0 0 0" />
      <geometry>
        <mesh
          filename="../meshes/left_hip_pitch.STL" />
      </geometry>
    </collision>
  </link>
  <joint
    name="left_hip_pitch_joint"
    type="revolute">
    <origin
      xyz="0 0 0"
      rpy="0 0 0" />
    <parent
      link="left_hip_roll" />
    <child
      link="left_hip_pitch" />
    <axis
      xyz="0 1 0" />
    <limit
      lower="0"
      upper="0"
      effort="0"
      velocity="0" />
  </joint>
  <link
    name="left_knee_pitch">
    <inertial>
      <origin
        xyz="-1.9169709838289E-16 -0.00857325265941816 -0.127010278601144"
        rpy="0 0 0" />
      <mass
        value="0.232718078417979" />
      <inertia
        ixx="0.000202660360914128"
        ixy="3.87937677644539E-21"
        ixz="-1.28952471042899E-19"
        iyy="0.000249803523853592"
        iyz="4.27797624204847E-20"
        izz="0.000106783585605481" />
    </inertial>
    <visual>
      <origin
        xyz="0 0 0"
        rpy="0 0 0" />
      <geometry>
        <mesh
          filename="../meshes/left_knee_pitch.STL" />
      </geometry>
      <material
        name="">
        <color
          rgba="1 1 1 1" />
      </material>
    </visual>
    <collision>
      <origin
        xyz="0 0 0"
        rpy="0 0 0" />
      <geometry>
        <mesh
          filename="../meshes/left_knee_pitch.STL" />
      </geometry>
    </collision>
  </link>
  <joint
    name="left_knee_pitch_joint"
    type="revolute">
    <origin
      xyz="0 0.0936181760425075 -0.14"
      rpy="0 0 0" />
    <parent
      link="left_hip_pitch" />
    <child
      link="left_knee_pitch" />
    <axis
      xyz="0 1 0" />
    <limit
      lower="0"
      upper="0"
      effort="0"
      velocity="0" />
  </joint>
  <link
    name="left_ankle_pitch">
    <inertial>
      <origin
        xyz="0.0165320915802278 0.000878638979678131 -0.0350036570544408"
        rpy="0 0 0" />
      <mass
        value="0.0934205516990419" />
      <inertia
        ixx="4.08203466514557E-05"
        ixy="1.35770948841668E-06"
        ixz="3.73111146640662E-07"
        iyy="0.000143785268215984"
        iyz="-2.85203021993324E-06"
        izz="0.000109322370322001" />
    </inertial>
    <visual>
      <origin
        xyz="0 0 0"
        rpy="0 0 0" />
      <geometry>
        <mesh
          filename="../meshes/left_ankle_pitch.STL" />
      </geometry>
      <material
        name="">
        <color
          rgba="1 1 1 1" />
      </material>
    </visual>
    <collision>
      <origin
        xyz="0 0 0"
        rpy="0 0 0" />
      <geometry>
        <mesh
          filename="../meshes/left_ankle_pitch.STL" />
      </geometry>
    </collision>
  </link>
  <joint
    name="left_ankle_pitch_joint"
    type="revolute">
    <origin
      xyz="0 0 -0.14"
      rpy="0 0 0" />
    <parent
      link="left_knee_pitch" />
    <child
      link="left_ankle_pitch" />
    <axis
      xyz="0 1 0" />
    <limit
      lower="0"
      upper="0"
      effort="0"
      velocity="0" />
  </joint>
  <link
    name="right_hip_yaw">
    <inertial>
      <origin
        xyz="-0.0148415027804522 -1.4227820776147E-05 0.00518098759586436"
        rpy="0 0 0" />
      <mass
        value="0.22770651071542" />
      <inertia
        ixx="0.00016064594987398"
        ixy="-1.05844380133239E-08"
        ixz="2.79494697437761E-06"
        iyy="0.000122883197379238"
        iyz="5.01180502056588E-08"
        izz="0.000114845036646105" />
    </inertial>
    <visual>
      <origin
        xyz="0 0 0"
        rpy="0 0 0" />
      <geometry>
        <mesh
          filename="../meshes/right_hip_yaw.STL" />
      </geometry>
      <material
        name="">
        <color
          rgba="1 1 1 1" />
      </material>
    </visual>
    <collision>
      <origin
        xyz="0 0 0"
        rpy="0 0 0" />
      <geometry>
        <mesh
          filename="../meshes/right_hip_yaw.STL" />
      </geometry>
    </collision>
  </link>
  <joint
    name="right_hip_yaw_joint"
    type="revolute">
    <origin
      xyz="0 -0.04 0"
      rpy="0 0 0" />
    <parent
      link="base" />
    <child
      link="right_hip_yaw" />
    <axis
      xyz="0 0 1" />
    <limit
      lower="0"
      upper="0"
      effort="0"
      velocity="0" />
  </joint>
  <link
    name="right_hip_roll">
    <inertial>
      <origin
        xyz="0.000168686556307084 -0.073253854275096 1.42428991107002E-05"
        rpy="0 0 0" />
      <mass
        value="0.22746544778837" />
      <inertia
        ixx="0.000139061664775468"
        ixy="-9.72203682012507E-07"
        ixz="3.27718468277944E-09"
        iyy="0.000154215112847962"
        iyz="5.57863354310647E-08"
        izz="0.000132221036670331" />
    </inertial>
    <visual>
      <origin
        xyz="0 0 0"
        rpy="0 0 0" />
      <geometry>
        <mesh
          filename="../meshes/right_hip_roll.STL" />
      </geometry>
      <material
        name="">
        <color
          rgba="1 1 1 1" />
      </material>
    </visual>
    <collision>
      <origin
        xyz="0 0 0"
        rpy="0 0 0" />
      <geometry>
        <mesh
          filename="../meshes/right_hip_roll.STL" />
      </geometry>
    </collision>
  </link>
  <joint
    name="right_hip_roll_joint"
    type="revolute">
    <origin
      xyz="0 0 0"
      rpy="0 0 0" />
    <parent
      link="right_hip_yaw" />
    <child
      link="right_hip_roll" />
    <axis
      xyz="1 0 0" />
    <limit
      lower="0"
      upper="0"
      effort="0"
      velocity="0" />
  </joint>
  <link
    name="right_hip_pitch">
    <inertial>
      <origin
        xyz="9.80659937259572E-17 -0.0845594117245176 -0.125225619873394"
        rpy="0 0 0" />
      <mass
        value="0.24023854356995" />
      <inertia
        ixx="0.000225138484662056"
        ixy="-5.10216785538961E-20"
        ixz="-1.59756425112216E-19"
        iyy="0.000288595828376715"
        iyz="-2.4227586952317E-20"
        izz="0.000123129101652142" />
    </inertial>
    <visual>
      <origin
        xyz="0 0 0"
        rpy="0 0 0" />
      <geometry>
        <mesh
          filename="../meshes/right_hip_pitch.STL" />
      </geometry>
      <material
        name="">
        <color
          rgba="1 1 1 1" />
      </material>
    </visual>
    <collision>
      <origin
        xyz="0 0 0"
        rpy="0 0 0" />
      <geometry>
        <mesh
          filename="../meshes/right_hip_pitch.STL" />
      </geometry>
    </collision>
  </link>
  <joint
    name="right_hip_pitch_joint"
    type="revolute">
    <origin
      xyz="0 0 0"
      rpy="0 0 0" />
    <parent
      link="right_hip_roll" />
    <child
      link="right_hip_pitch" />
    <axis
      xyz="0 -1 0" />
    <limit
      lower="0"
      upper="0"
      effort="0"
      velocity="0" />
  </joint>
  <link
    name="right_knee_pitch">
    <inertial>
      <origin
        xyz="-1.85737083378316E-16 0.00857325265941841 -0.127010278601144"
        rpy="0 0 0" />
      <mass
        value="0.232718078417979" />
      <inertia
        ixx="0.000202660360914127"
        ixy="-3.4191708323686E-20"
        ixz="-1.53618567240911E-19"
        iyy="0.000249803523853592"
        iyz="2.62948010064838E-20"
        izz="0.000106783585605481" />
    </inertial>
    <visual>
      <origin
        xyz="0 0 0"
        rpy="0 0 0" />
      <geometry>
        <mesh
          filename="../meshes/right_knee_pitch.STL" />
      </geometry>
      <material
        name="">
        <color
          rgba="1 1 1 1" />
      </material>
    </visual>
    <collision>
      <origin
        xyz="0 0 0"
        rpy="0 0 0" />
      <geometry>
        <mesh
          filename="../meshes/right_knee_pitch.STL" />
      </geometry>
    </collision>
  </link>
  <joint
    name="right_knee_pitch_joint"
    type="revolute">
    <origin
      xyz="0 -0.0936181760425084 -0.14"
      rpy="0 0 0" />
    <parent
      link="right_hip_pitch" />
    <child
      link="right_knee_pitch" />
    <axis
      xyz="0 -1 0" />
    <limit
      lower="0"
      upper="0"
      effort="0"
      velocity="0" />
  </joint>
  <link
    name="right_ankle_pitch">
    <inertial>
      <origin
        xyz="0.0165320706873633 -0.000878627774280077 -0.0350036769927607"
        rpy="0 0 0" />
      <mass
        value="0.0934206054212803" />
      <inertia
        ixx="4.08203779126198E-05"
        ixy="-1.35771959946846E-06"
        ixz="3.73028599539108E-07"
        iyy="0.00014378533207983"
        iyz="2.85193277907882E-06"
        izz="0.000109322408669691" />
    </inertial>
    <visual>
      <origin
        xyz="0 0 0"
        rpy="0 0 0" />
      <geometry>
        <mesh
          filename="../meshes/right_ankle_pitch.STL" />
      </geometry>
      <material
        name="">
        <color
          rgba="1 1 1 1" />
      </material>
    </visual>
    <collision>
      <origin
        xyz="0 0 0"
        rpy="0 0 0" />
      <geometry>
        <mesh
          filename="../meshes/right_ankle_pitch.STL" />
      </geometry>
    </collision>
  </link>
  <joint
    name="right_ankle_pitch_joint"
    type="revolute">
    <origin
      xyz="0 0 -0.14"
      rpy="0 0 0" />
    <parent
      link="right_knee_pitch" />
    <child
      link="right_ankle_pitch" />
    <axis
      xyz="0 -1 0" />
    <limit
      lower="0"
      upper="0"
      effort="0"
      velocity="0" />
  </joint>
  <link
    name="neck_pitch1">
    <inertial>
      <origin
        xyz="-4.16333634234434E-17 -0.00249999999999998 0.0510454762534523"
        rpy="0 0 0" />
      <mass
        value="0.10052370093748" />
      <inertia
        ixx="6.47635325993599E-05"
        ixy="1.98956536096706E-20"
        ixz="-3.1570869978831E-20"
        iyy="5.84221247072049E-05"
        iyz="-7.6727683019986E-21"
        izz="3.58020171039593E-05" />
    </inertial>
    <visual>
      <origin
        xyz="0 0 0"
        rpy="0 0 0" />
      <geometry>
        <mesh
          filename="../meshes/neck_pitch1.STL" />
      </geometry>
      <material
        name="">
        <color
          rgba="1 1 1 1" />
      </material>
    </visual>
    <collision>
      <origin
        xyz="0 0 0"
        rpy="0 0 0" />
      <geometry>
        <mesh
          filename="../meshes/neck_pitch1.STL" />
      </geometry>
    </collision>
  </link>
  <joint
    name="neck_pitch1_joint"
    type="revolute">
    <origin
      xyz="0.0774999999999999 0 0.108874586088177"
      rpy="0 0 0" />
    <parent
      link="base" />
    <child
      link="neck_pitch1" />
    <axis
      xyz="0 1 0" />
    <limit
      lower="0"
      upper="0"
      effort="0"
      velocity="0" />
  </joint>
  <link
    name="neck_pitch2">
    <inertial>
      <origin
        xyz="0.00575865504438706 -0.00249999999999993 0.0819986207442349"
        rpy="0 0 0" />
      <mass
        value="1.42018144140995" />
      <inertia
        ixx="0.00267437236982675"
        ixy="-6.51939881580211E-18"
        ixz="-6.35777999085746E-05"
        iyy="0.00462154299939655"
        iyz="7.23397178913587E-19"
        izz="0.00672091269381809" />
    </inertial>
    <visual>
      <origin
        xyz="0 0 0"
        rpy="0 0 0" />
      <geometry>
        <mesh
          filename="../meshes/neck_pitch2.STL" />
      </geometry>
      <material
        name="">
        <color
          rgba="1 1 1 1" />
      </material>
    </visual>
    <collision>
      <origin
        xyz="0 0 0"
        rpy="0 0 0" />
      <geometry>
        <mesh
          filename="../meshes/neck_pitch2.STL" />
      </geometry>
    </collision>
  </link>
  <joint
    name="neck_pitch2_joint"
    type="revolute">
    <origin
      xyz="0 0 0.08"
      rpy="0 0 0" />
    <parent
      link="neck_pitch1" />
    <child
      link="neck_pitch2" />
    <axis
      xyz="0 -1 0" />
    <limit
      lower="0"
      upper="0"
      effort="0"
      velocity="0" />
  </joint>
</robot>
